Workbook
Name start_day: '2026'!$P$10

Sheet 2026
C2: How to Use This Template
N4: Time Entry
C5: Step 1: | E5: Enter the Year
C7: Step 2: | E7: Choose the Start Day
O8: Year | P8: =IF(MONTH(TODAY())=12,YEAR(TODAY())+1,YEAR(TODAY()))
C9: Step 3: | E9: Customize the Theme Colors / Fonts
E10: Go to Page Layout > Themes to choose different colors and fonts. | O10: Start Day of Week | P10: 1
C12: Step 4: | E12: Print to Paper or PDF
E13: Print the entire workbook, or print only the selected worksheets.

Sheet July
AG1: Call Variances
C2: =DATE('2026'!P8,7,1) | AG2: Away: CBP - 2 weeks: Peds Inpatient: Stanek Med A: Mudondo/Strand OB: Johnson | AK2: GYN/CM: Gaspar NICU: Bower/Beutel R3 - Ortho: Lux R2 - Peds: Derm: Ultrasound: Bower
C4: =C5 | E4: =E5 | G4: =G5 | I4: =I5 | K4: =K5 | O4: =O5 | W4: =W5 | AG4: Tracking Data
C5: =$C$2-(WEEKDAY($C$2,1)-(start_day-1))-IF((WEEKDAY($C$2,1)-(start_day-1))<=0,7,0)+1 | E5: =C5+1 | G5: =E5+1 | I5: =G5+1 | K5: =I5+1 | O5: =K5+1 | W5: =O5+1 | AG5: Interns | AH5: Hard | AI5: Oehm | AJ5: Schutt | AK5: Stanek | AL5: Strand | AM5: Wohlgemuth | AN5: Total
I6: Oehm Lux | K6: Schutt Mautino | O6: Oehm Mudondo | W6: Schutt Kendrick | AH6: =COUNTIF($C$5:$AD$21,"*Hard*") | AI6: =COUNTIF($C$5:$AD$21,"*Oehm*") | AJ6: =COUNTIF($C$5:$AD$21,"*Schutt*") | AK6: =COUNTIF($C$5:$AD$21,"*Stanek*") | AL6: =COUNTIF($C$5:$AD$21,"*Strand*") | AM6: =COUNTIF($C$5:$AD$21,"*Wohlgemuth*") | AN6: =SUM(AH6:AM6)
C7: =W5+1
E8: =C7+1 | G8: =E8+1 | I8: =G8+1 | K8: =I8+1 | O8: =K8+1 | W8: =O8+1 | AG8: 2nd Years | AH8: Beutel | AI8: Bottke | AJ8: Bower | AK8: Gaspar | AL8: Kendrick | AM8: Patel | AN8: Sublette | AO8: Total
C9: Strand Patel | E9: Wohlgemuth Mautino | G9: Wohlgemuth Bottke | I9: Wohlgemuth Johnson | K9: Wohlgemuth Mautino | O9: Wohlgemuth Mudondo | W9: Oehm Beutel | AH9: =COUNTIF($C$5:$AD$21,"*Beutel*") | AI9: =COUNTIF($C$5:$AD$21,"*Bottke*") | AJ9: =COUNTIF($C$5:$AD$21,"*Bower*") | AK9: =COUNTIF($C$5:$AD$21,"*Gaspar*") | AL9: =COUNTIF($C$5:$AD$21,"*Kendrick*") | AM9: =COUNTIF($C$5:$AD$21,"*Patel*") | AN9: =COUNTIF($C$5:$AD$21,"*Sublette*") | AO9: =SUM(AH9:AN9)
C10: =W8+1
E11: =C10+1 | G11: =E11+1 | I11: =G11+1 | K11: =I11+1 | O11: =K11+1 | W11: =O11+1 | AG11: 3rd Years | AH11: Johnson | AI11: Lux | AJ11: Mautino | AK11: Mudondo | AL11: Total
C12: Hard Patel | E12: Wohlgemuth Mudondo | G12: Wohlgemuth Mautino | I12: Wohlgemuth Johnson | K12: Wohlgemuth Kendrick | O12: Wohlgemuth Mautino | W12: Strand Johnson | AH12: =COUNTIF($C$5:$AD$21,"*Johnson*") | AI12: =COUNTIF($C$5:$AD$21,"*Lux*") | AJ12: =COUNTIF($C$5:$AD$21,"*Mautino*") | AK12: =COUNTIF($C$5:$AD$21,"*Mudondo*") | AL12: =SUM(AH12:AK12)
C13: =W11+1
E14: =C13+1 | G14: =E14+1 | I14: =G14+1 | K14: =I14+1 | O14: =K14+1 | W14: =O14+1
C15: Oehm Kendrick | E15: Schutt Johnson | G15: Schutt Mudondo | I15: Schutt Bottke | K15: Schutt Johnson | O15: Schutt Mautino | W15: Strand Patel
C16: =W14+1
E17: =C16+1 | G17: =E17+1 | I17: =G17+1 | K17: =I17+1 | O17: =K17+1 | W17: =O17+1
C18: Oehm Kendrick | E18: Schutt Mautino | G18: Schutt Bower | I18: Schutt Lux | K18: Schutt Bower | O18: Schutt Johnson
C19: =W17+1
E20: =C19+1 | G20: =E20+1 | I20: =G20+1 | K20: =I20+1 | O20: =K20+1 | W20: =O20+1
C25: Notes | O25: =DATE(YEAR(C2),MONTH(C2)-1,1) | X25: =DATE(YEAR(C2),MONTH(C2)+1,1)
O26: =INDEX({"S";"M";"T";"W";"T";"F";"S"},1+MOD(start_day+1-2,7)) | P26: =INDEX({"S";"M";"T";"W";"T";"F";"S"},1+MOD(start_day+2-2,7)) | Q26: =INDEX({"S";"M";"T";"W";"T";"F";"S"},1+MOD(start_day+3-2,7)) | R26: =INDEX({"S";"M";"T";"W";"T";"F";"S"},1+MOD(start_day+4-2,7)) | S26: =INDEX({"S";"M";"T";"W";"T";"F";"S"},1+MOD(start_day+5-2,7)) | T26: =INDEX({"S";"M";"T";"W";"T";"F";"S"},1+MOD(start_day+6-2,7)) | U26: =INDEX({"S";"M";"T";"W";"T";"F";"S"},1+MOD(start_day+7-2,7)) | X26: =INDEX({"S";"M";"T";"W";"T";"F";"S"},1+MOD(start_day+1-2,7)) | Y26: =INDEX({"S";"M";"T";"W";"T";"F";"S"},1+MOD(start_day+2-2,7)) | Z26: =INDEX({"S";"M";"T";"W";"T";"F";"S"},1+MOD(start_day+3-2,7)) | AA26: =INDEX({"S";"M";"T";"W";"T";"F";"S"},1+MOD(start_day+4-2,7)) | AB26: =INDEX({"S";"M";"T";"W";"T";"F";"S"},1+MOD(start_day+5-2,7)) | AC26: =INDEX({"S";"M";"T";"W";"T";"F";"S"},1+MOD(start_day+6-2,7)) | AD26: =INDEX({"S";"M";"T";"W";"T";"F";"S"},1+MOD(start_day+7-2,7))
O27: =IF(MONTH($O$25)<>MONTH($O$25-(WEEKDAY($O$25,1)-(start_day-1))-IF((WEEKDAY($O$25,1)-(start_day-1))<=0,7,0)+(ROW(O27)-ROW($O$27))*7+(COLUMN(O27)-COLUMN($O$27)+1)),"",$O$25-(WEEKDAY($O$25,1)-(start_day-1))-IF((WEEKDAY($O$25,1)-(start_day-1))<=0,7,0)+(ROW(O27)-ROW($O$27))*7+(COLUMN(O27)-COLUMN($O$27)+1)) | P27: =IF(MONTH($O$25)<>MONTH($O$25-(WEEKDAY($O$25,1)-(start_day-1))-IF((WEEKDAY($O$25,1)-(start_day-1))<=0,7,0)+(ROW(P27)-ROW($O$27))*7+(COLUMN(P27)-COLUMN($O$27)+1)),"",$O$25-(WEEKDAY($O$25,1)-(start_day-1))-IF((WEEKDAY($O$25,1)-(start_day-1))<=0,7,0)+(ROW(P27)-ROW($O$27))*7+(COLUMN(P27)-COLUMN($O$27)+1)) | Q27: =IF(MONTH($O$25)<>MONTH($O$25-(WEEKDAY($O$25,1)-(start_day-1))-IF((WEEKDAY($O$25,1)-(start_day-1))<=0,7,0)+(ROW(Q27)-ROW($O$27))*7+(COLUMN(Q27)-COLUMN($O$27)+1)),"",$O$25-(WEEKDAY($O$25,1)-(start_day-1))-IF((WEEKDAY($O$25,1)-(start_day-1))<=0,7,0)+(ROW(Q27)-ROW($O$27))*7+(COLUMN(Q27)-COLUMN($O$27)+1)) | R27: =IF(MONTH($O$25)<>MONTH($O$25-(WEEKDAY($O$25,1)-(start_day-1))-IF((WEEKDAY($O$25,1)-(start_day-1))<=0,7,0)+(ROW(R27)-ROW($O$27))*7+(COLUMN(R27)-COLUMN($O$27)+1)),"",$O$25-(WEEKDAY($O$25,1)-(start_day-1))-IF((WEEKDAY($O$25,1)-(start_day-1))<=0,7,0)+(ROW(R27)-ROW($O$27))*7+(COLUMN(R27)-COLUMN($O$27)+1)) | S27: =IF(MONTH($O$25)<>MONTH($O$25-(WEEKDAY($O$25,1)-(start_day-1))-IF((WEEKDAY($O$25,1)-(start_day-1))<=0,7,0)+(ROW(S27)-ROW($O$27))*7+(COLUMN(S27)-COLUMN($O$27)+1)),"",$O$25-(WEEKDAY($O$25,1)-(start_day-1))-IF((WEEKDAY($O$25,1)-(start_day-1))<=0,7,0)+(ROW(S27)-ROW($O$27))*7+(COLUMN(S27)-COLUMN($O$27)+1)) | T27: =IF(MONTH($O$25)<>MONTH($O$25-(WEEKDAY($O$25,1)-(start_day-1))-IF((WEEKDAY($O$25,1)-(start_day-1))<=0,7,0)+(ROW(T27)-ROW($O$27))*7+(COLUMN(T27)-COLUMN($O$27)+1)),"",$O$25-(WEEKDAY($O$25,1)-(start_day-1))-IF((WEEKDAY($O$25,1)-(start_day-1))<=0,7,0)+(ROW(T27)-ROW($O$27))*7+(COLUMN(T27)-COLUMN($O$27)+1)) | U27: =IF(MONTH($O$25)<>MONTH($O$25-(WEEKDAY($O$25,1)-(start_day-1))-IF((WEEKDAY($O$25,1)-(start_day-1))<=0,7,0)+(ROW(U27)-ROW($O$27))*7+(COLUMN(U27)-COLUMN($O$27)+1)),"",$O$25-(WEEKDAY($O$25,1)-(start_day-1))-IF((WEEKDAY($O$25,1)-(start_day-1))<=0,7,0)+(ROW(U27)-ROW($O$27))*7+(COLUMN(U27)-COLUMN($O$27)+1)) | X27: =IF(MONTH($X$25)<>MONTH($X$25-(WEEKDAY($X$25,1)-(start_day-1))-IF((WEEKDAY($X$25,1)-(start_day-1))<=0,7,0)+(ROW(X27)-ROW($X$27))*7+(COLUMN(X27)-COLUMN($X$27)+1)),"",$X$25-(WEEKDAY($X$25,1)-(start_day-1))-IF((WEEKDAY($X$25,1)-(start_day-1))<=0,7,0)+(ROW(X27)-ROW($X$27))*7+(COLUMN(X27)-COLUMN($X$27)+1)) | Y27: =IF(MONTH($X$25)<>MONTH($X$25-(WEEKDAY($X$25,1)-(start_day-1))-IF((WEEKDAY($X$25,1)-(start_day-1))<=0,7,0)+(ROW(Y27)-ROW($X$27))*7+(COLUMN(Y27)-COLUMN($X$27)+1)),"",$X$25-(WEEKDAY($X$25,1)-(start_day-1))-IF((WEEKDAY($X$25,1)-(start_day-1))<=0,7,0)+(ROW(Y27)-ROW($X$27))*7+(COLUMN(Y27)-COLUMN($X$27)+1)) | Z27: =IF(MONTH($X$25)<>MONTH($X$25-(WEEKDAY($X$25,1)-(start_day-1))-IF((WEEKDAY($X$25,1)-(start_day-1))<=0,7,0)+(ROW(Z27)-ROW($X$27))*7+(COLUMN(Z27)-COLUMN($X$27)+1)),"",$X$25-(WEEKDAY($X$25,1)-(start_day-1))-IF((WEEKDAY($X$25,1)-(start_day-1))<=0,7,0)+(ROW(Z27)-ROW($X$27))*7+(COLUMN(Z27)-COLUMN($X$27)+1)) | AA27: =IF(MONTH($X$25)<>MONTH($X$25-(WEEKDAY($X$25,1)-(start_day-1))-IF((WEEKDAY($X$25,1)-(start_day-1))<=0,7,0)+(ROW(AA27)-ROW($X$27))*7+(COLUMN(AA27)-COLUMN($X$27)+1)),"",$X$25-(WEEKDAY($X$25,1)-(start_day-1))-IF((WEEKDAY($X$25,1)-(start_day-1))<=0,7,0)+(ROW(AA27)-ROW($X$27))*7+(COLUMN(AA27)-COLUMN($X$27)+1)) | AB27: =IF(MONTH($X$25)<>MONTH($X$25-(WEEKDAY($X$25,1)-(start_day-1))-IF((WEEKDAY($X$25,1)-(start_day-1))<=0,7,0)+(ROW(AB27)-ROW($X$27))*7+(COLUMN(AB27)-COLUMN($X$27)+1)),"",$X$25-(WEEKDAY($X$25,1)-(start_day-1))-IF((WEEKDAY($X$25,1)-(start_day-1))<=0,7,0)+(ROW(AB27)-ROW($X$27))*7+(COLUMN(AB27)-COLUMN($X$27)+1)) | AC27: =IF(MONTH($X$25)<>MONTH($X$25-(WEEKDAY($X$25,1)-(start_day-1))-IF((WEEKDAY($X$25,1)-(start_day-1))<=0,7,0)+(ROW(AC27)-ROW($X$27))*7+(COLUMN(AC27)-COLUMN($X$27)+1)),"",$X$25-(WEEKDAY($X$25,1)-(start_day-1))-IF((WEEKDAY($X$25,1)-(start_day-1))<=0,7,0)+(ROW(AC27)-ROW($X$27))*7+(COLUMN(AC27)-COLUMN($X$27)+1)) | AD27: =IF(MONTH($X$25)<>MONTH($X$25-(WEEKDAY($X$25,1)-(start_day-1))-IF((WEEKDAY($X$25,1)-(start_day-1))<=0,7,0)+(ROW(AD27)-ROW($X$27))*7+(COLUMN(AD27)-COLUMN($X$27)+1)),"",$X$25-(WEEKDAY($X$25,1)-(start_day-1))-IF((WEEKDAY($X$25,1)-(start_day-1))<=0,7,0)+(ROW(AD27)-ROW($X$27))*7+(COLUMN(AD27)-COLUMN($X$27)+1))
O28: =IF(MONTH($O$25)<>MONTH($O$25-(WEEKDAY($O$25,1)-(start_day-1))-IF((WEEKDAY($O$25,1)-(start_day-1))<=0,7,0)+(ROW(O28)-ROW($O$27))*7+(COLUMN(O28)-COLUMN($O$27)+1)),"",$O$25-(WEEKDAY($O$25,1)-(start_day-1))-IF((WEEKDAY($O$25,1)-(start_day-1))<=0,7,0)+(ROW(O28)-ROW($O$27))*7+(COLUMN(O28)-COLUMN($O$27)+1)) | P28: =IF(MONTH($O$25)<>MONTH($O$25-(WEEKDAY($O$25,1)-(start_day-1))-IF((WEEKDAY($O$25,1)-(start_day-1))<=0,7,0)+(ROW(P28)-ROW($O$27))*7+(COLUMN(P28)-COLUMN($O$27)+1)),"",$O$25-(WEEKDAY($O$25,1)-(start_day-1))-IF((WEEKDAY($O$25,1)-(start_day-1))<=0,7,0)+(ROW(P28)-ROW($O$27))*7+(COLUMN(P28)-COLUMN($O$27)+1)) | Q28: =IF(MONTH($O$25)<>MONTH($O$25-(WEEKDAY($O$25,1)-(start_day-1))-IF((WEEKDAY($O$25,1)-(start_day-1))<=0,7,0)+(ROW(Q28)-ROW($O$27))*7+(COLUMN(Q28)-COLUMN($O$27)+1)),"",$O$25-(WEEKDAY($O$25,1)-(start_day-1))-IF((WEEKDAY($O$25,1)-(start_day-1))<=0,7,0)+(ROW(Q28)-ROW($O$27))*7+(COLUMN(Q28)-COLUMN($O$27)+1)) | R28: =IF(MONTH($O$25)<>MONTH($O$25-(WEEKDAY($O$25,1)-(start_day-1))-IF((WEEKDAY($O$25,1)-(start_day-1))<=0,7,0)+(ROW(R28)-ROW($O$27))*7+(COLUMN(R28)-COLUMN($O$27)+1)),"",$O$25-(WEEKDAY($O$25,1)-(start_day-1))-IF((WEEKDAY($O$25,1)-(start_day-1))<=0,7,0)+(ROW(R28)-ROW($O$27))*7+(COLUMN(R28)-COLUMN($O$27)+1)) | S28: =IF(MONTH($O$25)<>MONTH($O$25-(WEEKDAY($O$25,1)-(start_day-1))-IF((WEEKDAY($O$25,1)-(start_day-1))<=0,7,0)+(ROW(S28)-ROW($O$27))*7+(COLUMN(S28)-COLUMN($O$27)+1)),"",$O$25-(WEEKDAY($O$25,1)-(start_day-1))-IF((WEEKDAY($O$25,1)-(start_day-1))<=0,7,0)+(ROW(S28)-ROW($O$27))*7+(COLUMN(S28)-COLUMN($O$27)+1)) | T28: =IF(MONTH($O$25)<>MONTH($O$25-(WEEKDAY($O$25,1)-(start_day-1))-IF((WEEKDAY($O$25,1)-(start_day-1))<=0,7,0)+(ROW(T28)-ROW($O$27))*7+(COLUMN(T28)-COLUMN($O$27)+1)),"",$O$25-(WEEKDAY($O$25,1)-(start_day-1))-IF((WEEKDAY($O$25,1)-(start_day-1))<=0,7,0)+(ROW(T28)-ROW($O$27))*7+(COLUMN(T28)-COLUMN($O$27)+1)) | U28: =IF(MONTH($O$25)<>MONTH($O$25-(WEEKDAY($O$25,1)-(start_day-1))-IF((WEEKDAY($O$25,1)-(start_day-1))<=0,7,0)+(ROW(U28)-ROW($O$27))*7+(COLUMN(U28)-COLUMN($O$27)+1)),"",$O$25-(WEEKDAY($O$25,1)-(start_day-1))-IF((WEEKDAY($O$25,1)-(start_day-1))<=0,7,0)+(ROW(U28)-ROW($O$27))*7+(COLUMN(U28)-COLUMN($O$27)+1)) | X28: =IF(MONTH($X$25)<>MONTH($X$25-(WEEKDAY($X$25,1)-(start_day-1))-IF((WEEKDAY($X$25,1)-(start_day-1))<=0,7,0)+(ROW(X28)-ROW($X$27))*7+(COLUMN(X28)-COLUMN($X$27)+1)),"",$X$25-(WEEKDAY($X$25,1)-(start_day-1))-IF((WEEKDAY($X$25,1)-(start_day-1))<=0,7,0)+(ROW(X28)-ROW($X$27))*7+(COLUMN(X28)-COLUMN($X$27)+1)) | Y28: =IF(MONTH($X$25)<>MONTH($X$25-(WEEKDAY($X$25,1)-(start_day-1))-IF((WEEKDAY($X$25,1)-(start_day-1))<=0,7,0)+(ROW(Y28)-ROW($X$27))*7+(COLUMN(Y28)-COLUMN($X$27)+1)),"",$X$25-(WEEKDAY($X$25,1)-(start_day-1))-IF((WEEKDAY($X$25,1)-(start_day-1))<=0,7,0)+(ROW(Y28)-ROW($X$27))*7+(COLUMN(Y28)-COLUMN($X$27)+1)) | Z28: =IF(MONTH($X$25)<>MONTH($X$25-(WEEKDAY($X$25,1)-(start_day-1))-IF((WEEKDAY($X$25,1)-(start_day-1))<=0,7,0)+(ROW(Z28)-ROW($X$27))*7+(COLUMN(Z28)-COLUMN($X$27)+1)),"",$X$25-(WEEKDAY($X$25,1)-(start_day-1))-IF((WEEKDAY($X$25,1)-(start_day-1))<=0,7,0)+(ROW(Z28)-ROW($X$27))*7+(COLUMN(Z28)-COLUMN($X$27)+1)) | AA28: =IF(MONTH($X$25)<>MONTH($X$25-(WEEKDAY($X$25,1)-(start_day-1))-IF((WEEKDAY($X$25,1)-(start_day-1))<=0,7,0)+(ROW(AA28)-ROW($X$27))*7+(COLUMN(AA28)-COLUMN($X$27)+1)),"",$X$25-(WEEKDAY($X$25,1)-(start_day-1))-IF((WEEKDAY($X$25,1)-(start_day-1))<=0,7,0)+(ROW(AA28)-ROW($X$27))*7+(COLUMN(AA28)-COLUMN($X$27)+1)) | AB28: =IF(MONTH($X$25)<>MONTH($X$25-(WEEKDAY($X$25,1)-(start_day-1))-IF((WEEKDAY($X$25,1)-(start_day-1))<=0,7,0)+(ROW(AB28)-ROW($X$27))*7+(COLUMN(AB28)-COLUMN($X$27)+1)),"",$X$25-(WEEKDAY($X$25,1)-(start_day-1))-IF((WEEKDAY($X$25,1)-(start_day-1))<=0,7,0)+(ROW(AB28)-ROW($X$27))*7+(COLUMN(AB28)-COLUMN($X$27)+1)) | AC28: =IF(MONTH($X$25)<>MONTH($X$25-(WEEKDAY($X$25,1)-(start_day-1))-IF((WEEKDAY($X$25,1)-(start_day-1))<=0,7,0)+(ROW(AC28)-ROW($X$27))*7+(COLUMN(AC28)-COLUMN($X$27)+1)),"",$X$25-(WEEKDAY($X$25,1)-(start_day-1))-IF((WEEKDAY($X$25,1)-(start_day-1))<=0,7,0)+(ROW(AC28)-ROW($X$27))*7+(COLUMN(AC28)-COLUMN($X$27)+1)) | AD28: =IF(MONTH($X$25)<>MONTH($X$25-(WEEKDAY($X$25,1)-(start_day-1))-IF((WEEKDAY($X$25,1)-(start_day-1))<=0,7,0)+(ROW(AD28)-ROW($X$27))*7+(COLUMN(AD28)-COLUMN($X$27)+1)),"",$X$25-(WEEKDAY($X$25,1)-(start_day-1))-IF((WEEKDAY($X$25,1)-(start_day-1))<=0,7,0)+(ROW(AD28)-ROW($X$27))*7+(COLUMN(AD28)-COLUMN($X$27)+1))
O29: =IF(MONTH($O$25)<>MONTH($O$25-(WEEKDAY($O$25,1)-(start_day-1))-IF((WEEKDAY($O$25,1)-(start_day-1))<=0,7,0)+(ROW(O29)-ROW($O$27))*7+(COLUMN(O29)-COLUMN($O$27)+1)),"",$O$25-(WEEKDAY($O$25,1)-(start_day-1))-IF((WEEKDAY($O$25,1)-(start_day-1))<=0,7,0)+(ROW(O29)-ROW($O$27))*7+(COLUMN(O29)-COLUMN($O$27)+1)) | P29: =IF(MONTH($O$25)<>MONTH($O$25-(WEEKDAY($O$25,1)-(start_day-1))-IF((WEEKDAY($O$25,1)-(start_day-1))<=0,7,0)+(ROW(P29)-ROW($O$27))*7+(COLUMN(P29)-COLUMN($O$27)+1)),"",$O$25-(WEEKDAY($O$25,1)-(start_day-1))-IF((WEEKDAY($O$25,1)-(start_day-1))<=0,7,0)+(ROW(P29)-ROW($O$27))*7+(COLUMN(P29)-COLUMN($O$27)+1)) | Q29: =IF(MONTH($O$25)<>MONTH($O$25-(WEEKDAY($O$25,1)-(start_day-1))-IF((WEEKDAY($O$25,1)-(start_day-1))<=0,7,0)+(ROW(Q29)-ROW($O$27))*7+(COLUMN(Q29)-COLUMN($O$27)+1)),"",$O$25-(WEEKDAY($O$25,1)-(start_day-1))-IF((WEEKDAY($O$25,1)-(start_day-1))<=0,7,0)+(ROW(Q29)-ROW($O$27))*7+(COLUMN(Q29)-COLUMN($O$27)+1)) | R29: =IF(MONTH($O$25)<>MONTH($O$25-(WEEKDAY($O$25,1)-(start_day-1))-IF((WEEKDAY($O$25,1)-(start_day-1))<=0,7,0)+(ROW(R29)-ROW($O$27))*7+(COLUMN(R29)-COLUMN($O$27)+1)),"",$O$25-(WEEKDAY($O$25,1)-(start_day-1))-IF((WEEKDAY($O$25,1)-(start_day-1))<=0,7,0)+(ROW(R29)-ROW($O$27))*7+(COLUMN(R29)-COLUMN($O$27)+1)) | S29: =IF(MONTH($O$25)<>MONTH($O$25-(WEEKDAY($O$25,1)-(start_day-1))-IF((WEEKDAY($O$25,1)-(start_day-1))<=0,7,0)+(ROW(S29)-ROW($O$27))*7+(COLUMN(S29)-COLUMN($O$27)+1)),"",$O$25-(WEEKDAY($O$25,1)-(start_day-1))-IF((WEEKDAY($O$25,1)-(start_day-1))<=0,7,0)+(ROW(S29)-ROW($O$27))*7+(COLUMN(S29)-COLUMN($O$27)+1)) | T29: =IF(MONTH($O$25)<>MONTH($O$25-(WEEKDAY($O$25,1)-(start_day-1))-IF((WEEKDAY($O$25,1)-(start_day-1))<=0,7,0)+(ROW(T29)-ROW($O$27))*7+(COLUMN(T29)-COLUMN($O$27)+1)),"",$O$25-(WEEKDAY($O$25,1)-(start_day-1))-IF((WEEKDAY($O$25,1)-(start_day-1))<=0,7,0)+(ROW(T29)-ROW($O$27))*7+(COLUMN(T29)-COLUMN($O$27)+1)) | U29: =IF(MONTH($O$25)<>MONTH($O$25-(WEEKDAY($O$25,1)-(start_day-1))-IF((WEEKDAY($O$25,1)-(start_day-1))<=0,7,0)+(ROW(U29)-ROW($O$27))*7+(COLUMN(U29)-COLUMN($O$27)+1)),"",$O$25-(WEEKDAY($O$25,1)-(start_day-1))-IF((WEEKDAY($O$25,1)-(start_day-1))<=0,7,0)+(ROW(U29)-ROW($O$27))*7+(COLUMN(U29)-COLUMN($O$27)+1)) | X29: =IF(MONTH($X$25)<>MONTH($X$25-(WEEKDAY($X$25,1)-(start_day-1))-IF((WEEKDAY($X$25,1)-(start_day-1))<=0,7,0)+(ROW(X29)-ROW($X$27))*7+(COLUMN(X29)-COLUMN($X$27)+1)),"",$X$25-(WEEKDAY($X$25,1)-(start_day-1))-IF((WEEKDAY($X$25,1)-(start_day-1))<=0,7,0)+(ROW(X29)-ROW($X$27))*7+(COLUMN(X29)-COLUMN($X$27)+1)) | Y29: =IF(MONTH($X$25)<>MONTH($X$25-(WEEKDAY($X$25,1)-(start_day-1))-IF((WEEKDAY($X$25,1)-(start_day-1))<=0,7,0)+(ROW(Y29)-ROW($X$27))*7+(COLUMN(Y29)-COLUMN($X$27)+1)),"",$X$25-(WEEKDAY($X$25,1)-(start_day-1))-IF((WEEKDAY($X$25,1)-(start_day-1))<=0,7,0)+(ROW(Y29)-ROW($X$27))*7+(COLUMN(Y29)-COLUMN($X$27)+1)) | Z29: =IF(MONTH($X$25)<>MONTH($X$25-(WEEKDAY($X$25,1)-(start_day-1))-IF((WEEKDAY($X$25,1)-(start_day-1))<=0,7,0)+(ROW(Z29)-ROW($X$27))*7+(COLUMN(Z29)-COLUMN($X$27)+1)),"",$X$25-(WEEKDAY($X$25,1)-(start_day-1))-IF((WEEKDAY($X$25,1)-(start_day-1))<=0,7,0)+(ROW(Z29)-ROW($X$27))*7+(COLUMN(Z29)-COLUMN($X$27)+1)) | AA29: =IF(MONTH($X$25)<>MONTH($X$25-(WEEKDAY($X$25,1)-(start_day-1))-IF((WEEKDAY($X$25,1)-(start_day-1))<=0,7,0)+(ROW(AA29)-ROW($X$27))*7+(COLUMN(AA29)-COLUMN($X$27)+1)),"",$X$25-(WEEKDAY($X$25,1)-(start_day-1))-IF((WEEKDAY($X$25,1)-(start_day-1))<=0,7,0)+(ROW(AA29)-ROW($X$27))*7+(COLUMN(AA29)-COLUMN($X$27)+1)) | AB29: =IF(MONTH($X$25)<>MONTH($X$25-(WEEKDAY($X$25,1)-(start_day-1))-IF((WEEKDAY($X$25,1)-(start_day-1))<=0,7,0)+(ROW(AB29)-ROW($X$27))*7+(COLUMN(AB29)-COLUMN($X$27)+1)),"",$X$25-(WEEKDAY($X$25,1)-(start_day-1))-IF((WEEKDAY($X$25,1)-(start_day-1))<=0,7,0)+(ROW(AB29)-ROW($X$27))*7+(COLUMN(AB29)-COLUMN($X$27)+1)) | AC29: =IF(MONTH($X$25)<>MONTH($X$25-(WEEKDAY($X$25,1)-(start_day-1))-IF((WEEKDAY($X$25,1)-(start_day-1))<=0,7,0)+(ROW(AC29)-ROW($X$27))*7+(COLUMN(AC29)-COLUMN($X$27)+1)),"",$X$25-(WEEKDAY($X$25,1)-(start_day-1))-IF((WEEKDAY($X$25,1)-(start_day-1))<=0,7,0)+(ROW(AC29)-ROW($X$27))*7+(COLUMN(AC29)-COLUMN($X$27)+1)) | AD29: =IF(MONTH($X$25)<>MONTH($X$25-(WEEKDAY($X$25,1)-(start_day-1))-IF((WEEKDAY($X$25,1)-(start_day-1))<=0,7,0)+(ROW(AD29)-ROW($X$27))*7+(COLUMN(AD29)-COLUMN($X$27)+1)),"",$X$25-(WEEKDAY($X$25,1)-(start_day-1))-IF((WEEKDAY($X$25,1)-(start_day-1))<=0,7,0)+(ROW(AD29)-ROW($X$27))*7+(COLUMN(AD29)-COLUMN($X$27)+1))
O30: =IF(MONTH($O$25)<>MONTH($O$25-(WEEKDAY($O$25,1)-(start_day-1))-IF((WEEKDAY($O$25,1)-(start_day-1))<=0,7,0)+(ROW(O30)-ROW($O$27))*7+(COLUMN(O30)-COLUMN($O$27)+1)),"",$O$25-(WEEKDAY($O$25,1)-(start_day-1))-IF((WEEKDAY($O$25,1)-(start_day-1))<=0,7,0)+(ROW(O30)-ROW($O$27))*7+(COLUMN(O30)-COLUMN($O$27)+1)) | P30: =IF(MONTH($O$25)<>MONTH($O$25-(WEEKDAY($O$25,1)-(start_day-1))-IF((WEEKDAY($O$25,1)-(start_day-1))<=0,7,0)+(ROW(P30)-ROW($O$27))*7+(COLUMN(P30)-COLUMN($O$27)+1)),"",$O$25-(WEEKDAY($O$25,1)-(start_day-1))-IF((WEEKDAY($O$25,1)-(start_day-1))<=0,7,0)+(ROW(P30)-ROW($O$27))*7+(COLUMN(P30)-COLUMN($O$27)+1)) | Q30: =IF(MONTH($O$25)<>MONTH($O$25-(WEEKDAY($O$25,1)-(start_day-1))-IF((WEEKDAY($O$25,1)-(start_day-1))<=0,7,0)+(ROW(Q30)-ROW($O$27))*7+(COLUMN(Q30)-COLUMN($O$27)+1)),"",$O$25-(WEEKDAY($O$25,1)-(start_day-1))-IF((WEEKDAY($O$25,1)-(start_day-1))<=0,7,0)+(ROW(Q30)-ROW($O$27))*7+(COLUMN(Q30)-COLUMN($O$27)+1)) | R30: =IF(MONTH($O$25)<>MONTH($O$25-(WEEKDAY($O$25,1)-(start_day-1))-IF((WEEKDAY($O$25,1)-(start_day-1))<=0,7,0)+(ROW(R30)-ROW($O$27))*7+(COLUMN(R30)-COLUMN($O$27)+1)),"",$O$25-(WEEKDAY($O$25,1)-(start_day-1))-IF((WEEKDAY($O$25,1)-(start_day-1))<=0,7,0)+(ROW(R30)-ROW($O$27))*7+(COLUMN(R30)-COLUMN($O$27)+1)) | S30: =IF(MONTH($O$25)<>MONTH($O$25-(WEEKDAY($O$25,1)-(start_day-1))-IF((WEEKDAY($O$25,1)-(start_day-1))<=0,7,0)+(ROW(S30)-ROW($O$27))*7+(COLUMN(S30)-COLUMN($O$27)+1)),"",$O$25-(WEEKDAY($O$25,1)-(start_day-1))-IF((WEEKDAY($O$25,1)-(start_day-1))<=0,7,0)+(ROW(S30)-ROW($O$27))*7+(COLUMN(S30)-COLUMN($O$27)+1)) | T30: =IF(MONTH($O$25)<>MONTH($O$25-(WEEKDAY($O$25,1)-(start_day-1))-IF((WEEKDAY($O$25,1)-(start_day-1))<=0,7,0)+(ROW(T30)-ROW($O$27))*7+(COLUMN(T30)-COLUMN($O$27)+1)),"",$O$25-(WEEKDAY($O$25,1)-(start_day-1))-IF((WEEKDAY($O$25,1)-(start_day-1))<=0,7,0)+(ROW(T30)-ROW($O$27))*7+(COLUMN(T30)-COLUMN($O$27)+1)) | U30: =IF(MONTH($O$25)<>MONTH($O$25-(WEEKDAY($O$25,1)-(start_day-1))-IF((WEEKDAY($O$25,1)-(start_day-1))<=0,7,0)+(ROW(U30)-ROW($O$27))*7+(COLUMN(U30)-COLUMN($O$27)+1)),"",$O$25-(WEEKDAY($O$25,1)-(start_day-1))-IF((WEEKDAY($O$25,1)-(start_day-1))<=0,7,0)+(ROW(U30)-ROW($O$27))*7+(COLUMN(U30)-COLUMN($O$27)+1)) | X30: =IF(MONTH($X$25)<>MONTH($X$25-(WEEKDAY($X$25,1)-(start_day-1))-IF((WEEKDAY($X$25,1)-(start_day-1))<=0,7,0)+(ROW(X30)-ROW($X$27))*7+(COLUMN(X30)-COLUMN($X$27)+1)),"",$X$25-(WEEKDAY($X$25,1)-(start_day-1))-IF((WEEKDAY($X$25,1)-(start_day-1))<=0,7,0)+(ROW(X30)-ROW($X$27))*7+(COLUMN(X30)-COLUMN($X$27)+1)) | Y30: =IF(MONTH($X$25)<>MONTH($X$25-(WEEKDAY($X$25,1)-(start_day-1))-IF((WEEKDAY($X$25,1)-(start_day-1))<=0,7,0)+(ROW(Y30)-ROW($X$27))*7+(COLUMN(Y30)-COLUMN($X$27)+1)),"",$X$25-(WEEKDAY($X$25,1)-(start_day-1))-IF((WEEKDAY($X$25,1)-(start_day-1))<=0,7,0)+(ROW(Y30)-ROW($X$27))*7+(COLUMN(Y30)-COLUMN($X$27)+1)) | Z30: =IF(MONTH($X$25)<>MONTH($X$25-(WEEKDAY($X$25,1)-(start_day-1))-IF((WEEKDAY($X$25,1)-(start_day-1))<=0,7,0)+(ROW(Z30)-ROW($X$27))*7+(COLUMN(Z30)-COLUMN($X$27)+1)),"",$X$25-(WEEKDAY($X$25,1)-(start_day-1))-IF((WEEKDAY($X$25,1)-(start_day-1))<=0,7,0)+(ROW(Z30)-ROW($X$27))*7+(COLUMN(Z30)-COLUMN($X$27)+1)) | AA30: =IF(MONTH($X$25)<>MONTH($X$25-(WEEKDAY($X$25,1)-(start_day-1))-IF((WEEKDAY($X$25,1)-(start_day-1))<=0,7,0)+(ROW(AA30)-ROW($X$27))*7+(COLUMN(AA30)-COLUMN($X$27)+1)),"",$X$25-(WEEKDAY($X$25,1)-(start_day-1))-IF((WEEKDAY($X$25,1)-(start_day-1))<=0,7,0)+(ROW(AA30)-ROW($X$27))*7+(COLUMN(AA30)-COLUMN($X$27)+1)) | AB30: =IF(MONTH($X$25)<>MONTH($X$25-(WEEKDAY($X$25,1)-(start_day-1))-IF((WEEKDAY($X$25,1)-(start_day-1))<=0,7,0)+(ROW(AB30)-ROW($X$27))*7+(COLUMN(AB30)-COLUMN($X$27)+1)),"",$X$25-(WEEKDAY($X$25,1)-(start_day-1))-IF((WEEKDAY($X$25,1)-(start_day-1))<=0,7,0)+(ROW(AB30)-ROW($X$27))*7+(COLUMN(AB30)-COLUMN($X$27)+1)) | AC30: =IF(MONTH($X$25)<>MONTH($X$25-(WEEKDAY($X$25,1)-(start_day-1))-IF((WEEKDAY($X$25,1)-(start_day-1))<=0,7,0)+(ROW(AC30)-ROW($X$27))*7+(COLUMN(AC30)-COLUMN($X$27)+1)),"",$X$25-(WEEKDAY($X$25,1)-(start_day-1))-IF((WEEKDAY($X$25,1)-(start_day-1))<=0,7,0)+(ROW(AC30)-ROW($X$27))*7+(COLUMN(AC30)-COLUMN($X$27)+1)) | AD30: =IF(MONTH($X$25)<>MONTH($X$25-(WEEKDAY($X$25,1)-(start_day-1))-IF((WEEKDAY($X$25,1)-(start_day-1))<=0,7,0)+(ROW(AD30)-ROW($X$27))*7+(COLUMN(AD30)-COLUMN($X$27)+1)),"",$X$25-(WEEKDAY($X$25,1)-(start_day-1))-IF((WEEKDAY($X$25,1)-(start_day-1))<=0,7,0)+(ROW(AD30)-ROW($X$27))*7+(COLUMN(AD30)-COLUMN($X$27)+1))
O31: =IF(MONTH($O$25)<>MONTH($O$25-(WEEKDAY($O$25,1)-(start_day-1))-IF((WEEKDAY($O$25,1)-(start_day-1))<=0,7,0)+(ROW(O31)-ROW($O$27))*7+(COLUMN(O31)-COLUMN($O$27)+1)),"",$O$25-(WEEKDAY($O$25,1)-(start_day-1))-IF((WEEKDAY($O$25,1)-(start_day-1))<=0,7,0)+(ROW(O31)-ROW($O$27))*7+(COLUMN(O31)-COLUMN($O$27)+1)) | P31: =IF(MONTH($O$25)<>MONTH($O$25-(WEEKDAY($O$25,1)-(start_day-1))-IF((WEEKDAY($O$25,1)-(start_day-1))<=0,7,0)+(ROW(P31)-ROW($O$27))*7+(COLUMN(P31)-COLUMN($O$27)+1)),"",$O$25-(WEEKDAY($O$25,1)-(start_day-1))-IF((WEEKDAY($O$25,1)-(start_day-1))<=0,7,0)+(ROW(P31)-ROW($O$27))*7+(COLUMN(P31)-COLUMN($O$27)+1)) | Q31: =IF(MONTH($O$25)<>MONTH($O$25-(WEEKDAY($O$25,1)-(start_day-1))-IF((WEEKDAY($O$25,1)-(start_day-1))<=0,7,0)+(ROW(Q31)-ROW($O$27))*7+(COLUMN(Q31)-COLUMN($O$27)+1)),"",$O$25-(WEEKDAY($O$25,1)-(start_day-1))-IF((WEEKDAY($O$25,1)-(start_day-1))<=0,7,0)+(ROW(Q31)-ROW($O$27))*7+(COLUMN(Q31)-COLUMN($O$27)+1)) | R31: =IF(MONTH($O$25)<>MONTH($O$25-(WEEKDAY($O$25,1)-(start_day-1))-IF((WEEKDAY($O$25,1)-(start_day-1))<=0,7,0)+(ROW(R31)-ROW($O$27))*7+(COLUMN(R31)-COLUMN($O$27)+1)),"",$O$25-(WEEKDAY($O$25,1)-(start_day-1))-IF((WEEKDAY($O$25,1)-(start_day-1))<=0,7,0)+(ROW(R31)-ROW($O$27))*7+(COLUMN(R31)-COLUMN($O$27)+1)) | S31: =IF(MONTH($O$25)<>MONTH($O$25-(WEEKDAY($O$25,1)-(start_day-1))-IF((WEEKDAY($O$25,1)-(start_day-1))<=0,7,0)+(ROW(S31)-ROW($O$27))*7+(COLUMN(S31)-COLUMN($O$27)+1)),"",$O$25-(WEEKDAY($O$25,1)-(start_day-1))-IF((WEEKDAY($O$25,1)-(start_day-1))<=0,7,0)+(ROW(S31)-ROW($O$27))*7+(COLUMN(S31)-COLUMN($O$27)+1)) | T31: =IF(MONTH($O$25)<>MONTH($O$25-(WEEKDAY($O$25,1)-(start_day-1))-IF((WEEKDAY($O$25,1)-(start_day-1))<=0,7,0)+(ROW(T31)-ROW($O$27))*7+(COLUMN(T31)-COLUMN($O$27)+1)),"",$O$25-(WEEKDAY($O$25,1)-(start_day-1))-IF((WEEKDAY($O$25,1)-(start_day-1))<=0,7,0)+(ROW(T31)-ROW($O$27))*7+(COLUMN(T31)-COLUMN($O$27)+1)) | U31: =IF(MONTH($O$25)<>MONTH($O$25-(WEEKDAY($O$25,1)-(start_day-1))-IF((WEEKDAY($O$25,1)-(start_day-1))<=0,7,0)+(ROW(U31)-ROW($O$27))*7+(COLUMN(U31)-COLUMN($O$27)+1)),"",$O$25-(WEEKDAY($O$25,1)-(start_day-1))-IF((WEEKDAY($O$25,1)-(start_day-1))<=0,7,0)+(ROW(U31)-ROW($O$27))*7+(COLUMN(U31)-COLUMN($O$27)+1)) | X31: =IF(MONTH($X$25)<>MONTH($X$25-(WEEKDAY($X$25,1)-(start_day-1))-IF((WEEKDAY($X$25,1)-(start_day-1))<=0,7,0)+(ROW(X31)-ROW($X$27))*7+(COLUMN(X31)-COLUMN($X$27)+1)),"",$X$25-(WEEKDAY($X$25,1)-(start_day-1))-IF((WEEKDAY($X$25,1)-(start_day-1))<=0,7,0)+(ROW(X31)-ROW($X$27))*7+(COLUMN(X31)-COLUMN($X$27)+1)) | Y31: =IF(MONTH($X$25)<>MONTH($X$25-(WEEKDAY($X$25,1)-(start_day-1))-IF((WEEKDAY($X$25,1)-(start_day-1))<=0,7,0)+(ROW(Y31)-ROW($X$27))*7+(COLUMN(Y31)-COLUMN($X$27)+1)),"",$X$25-(WEEKDAY($X$25,1)-(start_day-1))-IF((WEEKDAY($X$25,1)-(start_day-1))<=0,7,0)+(ROW(Y31)-ROW($X$27))*7+(COLUMN(Y31)-COLUMN($X$27)+1)) | Z31: =IF(MONTH($X$25)<>MONTH($X$25-(WEEKDAY($X$25,1)-(start_day-1))-IF((WEEKDAY($X$25,1)-(start_day-1))<=0,7,0)+(ROW(Z31)-ROW($X$27))*7+(COLUMN(Z31)-COLUMN($X$27)+1)),"",$X$25-(WEEKDAY($X$25,1)-(start_day-1))-IF((WEEKDAY($X$25,1)-(start_day-1))<=0,7,0)+(ROW(Z31)-ROW($X$27))*7+(COLUMN(Z31)-COLUMN($X$27)+1)) | AA31: =IF(MONTH($X$25)<>MONTH($X$25-(WEEKDAY($X$25,1)-(start_day-1))-IF((WEEKDAY($X$25,1)-(start_day-1))<=0,7,0)+(ROW(AA31)-ROW($X$27))*7+(COLUMN(AA31)-COLUMN($X$27)+1)),"",$X$25-(WEEKDAY($X$25,1)-(start_day-1))-IF((WEEKDAY($X$25,1)-(start_day-1))<=0,7,0)+(ROW(AA31)-ROW($X$27))*7+(COLUMN(AA31)-COLUMN($X$27)+1)) | AB31: =IF(MONTH($X$25)<>MONTH($X$25-(WEEKDAY($X$25,1)-(start_day-1))-IF((WEEKDAY($X$25,1)-(start_day-1))<=0,7,0)+(ROW(AB31)-ROW($X$27))*7+(COLUMN(AB31)-COLUMN($X$27)+1)),"",$X$25-(WEEKDAY($X$25,1)-(start_day-1))-IF((WEEKDAY($X$25,1)-(start_day-1))<=0,7,0)+(ROW(AB31)-ROW($X$27))*7+(COLUMN(AB31)-COLUMN($X$27)+1)) | AC31: =IF(MONTH($X$25)<>MONTH($X$25-(WEEKDAY($X$25,1)-(start_day-1))-IF((WEEKDAY($X$25,1)-(start_day-1))<=0,7,0)+(ROW(AC31)-ROW($X$27))*7+(COLUMN(AC31)-COLUMN($X$27)+1)),"",$X$25-(WEEKDAY($X$25,1)-(start_day-1))-IF((WEEKDAY($X$25,1)-(start_day-1))<=0,7,0)+(ROW(AC31)-ROW($X$27))*7+(COLUMN(AC31)-COLUMN($X$27)+1)) | AD31: =IF(MONTH($X$25)<>MONTH($X$25-(WEEKDAY($X$25,1)-(start_day-1))-IF((WEEKDAY($X$25,1)-(start_day-1))<=0,7,0)+(ROW(AD31)-ROW($X$27))*7+(COLUMN(AD31)-COLUMN($X$27)+1)),"",$X$25-(WEEKDAY($X$25,1)-(start_day-1))-IF((WEEKDAY($X$25,1)-(start_day-1))<=0,7,0)+(ROW(AD31)-ROW($X$27))*7+(COLUMN(AD31)-COLUMN($X$27)+1))
O32: =IF(MONTH($O$25)<>MONTH($O$25-(WEEKDAY($O$25,1)-(start_day-1))-IF((WEEKDAY($O$25,1)-(start_day-1))<=0,7,0)+(ROW(O32)-ROW($O$27))*7+(COLUMN(O32)-COLUMN($O$27)+1)),"",$O$25-(WEEKDAY($O$25,1)-(start_day-1))-IF((WEEKDAY($O$25,1)-(start_day-1))<=0,7,0)+(ROW(O32)-ROW($O$27))*7+(COLUMN(O32)-COLUMN($O$27)+1)) | P32: =IF(MONTH($O$25)<>MONTH($O$25-(WEEKDAY($O$25,1)-(start_day-1))-IF((WEEKDAY($O$25,1)-(start_day-1))<=0,7,0)+(ROW(P32)-ROW($O$27))*7+(COLUMN(P32)-COLUMN($O$27)+1)),"",$O$25-(WEEKDAY($O$25,1)-(start_day-1))-IF((WEEKDAY($O$25,1)-(start_day-1))<=0,7,0)+(ROW(P32)-ROW($O$27))*7+(COLUMN(P32)-COLUMN($O$27)+1)) | Q32: =IF(MONTH($O$25)<>MONTH($O$25-(WEEKDAY($O$25,1)-(start_day-1))-IF((WEEKDAY($O$25,1)-(start_day-1))<=0,7,0)+(ROW(Q32)-ROW($O$27))*7+(COLUMN(Q32)-COLUMN($O$27)+1)),"",$O$25-(WEEKDAY($O$25,1)-(start_day-1))-IF((WEEKDAY($O$25,1)-(start_day-1))<=0,7,0)+(ROW(Q32)-ROW($O$27))*7+(COLUMN(Q32)-COLUMN($O$27)+1)) | R32: =IF(MONTH($O$25)<>MONTH($O$25-(WEEKDAY($O$25,1)-(start_day-1))-IF((WEEKDAY($O$25,1)-(start_day-1))<=0,7,0)+(ROW(R32)-ROW($O$27))*7+(COLUMN(R32)-COLUMN($O$27)+1)),"",$O$25-(WEEKDAY($O$25,1)-(start_day-1))-IF((WEEKDAY($O$25,1)-(start_day-1))<=0,7,0)+(ROW(R32)-ROW($O$27))*7+(COLUMN(R32)-COLUMN($O$27)+1)) | S32: =IF(MONTH($O$25)<>MONTH($O$25-(WEEKDAY($O$25,1)-(start_day-1))-IF((WEEKDAY($O$25,1)-(start_day-1))<=0,7,0)+(ROW(S32)-ROW($O$27))*7+(COLUMN(S32)-COLUMN($O$27)+1)),"",$O$25-(WEEKDAY($O$25,1)-(start_day-1))-IF((WEEKDAY($O$25,1)-(start_day-1))<=0,7,0)+(ROW(S32)-ROW($O$27))*7+(COLUMN(S32)-COLUMN($O$27)+1)) | T32: =IF(MONTH($O$25)<>MONTH($O$25-(WEEKDAY($O$25,1)-(start_day-1))-IF((WEEKDAY($O$25,1)-(start_day-1))<=0,7,0)+(ROW(T32)-ROW($O$27))*7+(COLUMN(T32)-COLUMN($O$27)+1)),"",$O$25-(WEEKDAY($O$25,1)-(start_day-1))-IF((WEEKDAY($O$25,1)-(start_day-1))<=0,7,0)+(ROW(T32)-ROW($O$27))*7+(COLUMN(T32)-COLUMN($O$27)+1)) | U32: =IF(MONTH($O$25)<>MONTH($O$25-(WEEKDAY($O$25,1)-(start_day-1))-IF((WEEKDAY($O$25,1)-(start_day-1))<=0,7,0)+(ROW(U32)-ROW($O$27))*7+(COLUMN(U32)-COLUMN($O$27)+1)),"",$O$25-(WEEKDAY($O$25,1)-(start_day-1))-IF((WEEKDAY($O$25,1)-(start_day-1))<=0,7,0)+(ROW(U32)-ROW($O$27))*7+(COLUMN(U32)-COLUMN($O$27)+1)) | X32: =IF(MONTH($X$25)<>MONTH($X$25-(WEEKDAY($X$25,1)-(start_day-1))-IF((WEEKDAY($X$25,1)-(start_day-1))<=0,7,0)+(ROW(X32)-ROW($X$27))*7+(COLUMN(X32)-COLUMN($X$27)+1)),"",$X$25-(WEEKDAY($X$25,1)-(start_day-1))-IF((WEEKDAY($X$25,1)-(start_day-1))<=0,7,0)+(ROW(X32)-ROW($X$27))*7+(COLUMN(X32)-COLUMN($X$27)+1)) | Y32: =IF(MONTH($X$25)<>MONTH($X$25-(WEEKDAY($X$25,1)-(start_day-1))-IF((WEEKDAY($X$25,1)-(start_day-1))<=0,7,0)+(ROW(Y32)-ROW($X$27))*7+(COLUMN(Y32)-COLUMN($X$27)+1)),"",$X$25-(WEEKDAY($X$25,1)-(start_day-1))-IF((WEEKDAY($X$25,1)-(start_day-1))<=0,7,0)+(ROW(Y32)-ROW($X$27))*7+(COLUMN(Y32)-COLUMN($X$27)+1)) | Z32: =IF(MONTH($X$25)<>MONTH($X$25-(WEEKDAY($X$25,1)-(start_day-1))-IF((WEEKDAY($X$25,1)-(start_day-1))<=0,7,0)+(ROW(Z32)-ROW($X$27))*7+(COLUMN(Z32)-COLUMN($X$27)+1)),"",$X$25-(WEEKDAY($X$25,1)-(start_day-1))-IF((WEEKDAY($X$25,1)-(start_day-1))<=0,7,0)+(ROW(Z32)-ROW($X$27))*7+(COLUMN(Z32)-COLUMN($X$27)+1)) | AA32: =IF(MONTH($X$25)<>MONTH($X$25-(WEEKDAY($X$25,1)-(start_day-1))-IF((WEEKDAY($X$25,1)-(start_day-1))<=0,7,0)+(ROW(AA32)-ROW($X$27))*7+(COLUMN(AA32)-COLUMN($X$27)+1)),"",$X$25-(WEEKDAY($X$25,1)-(start_day-1))-IF((WEEKDAY($X$25,1)-(start_day-1))<=0,7,0)+(ROW(AA32)-ROW($X$27))*7+(COLUMN(AA32)-COLUMN($X$27)+1)) | AB32: =IF(MONTH($X$25)<>MONTH($X$25-(WEEKDAY($X$25,1)-(start_day-1))-IF((WEEKDAY($X$25,1)-(start_day-1))<=0,7,0)+(ROW(AB32)-ROW($X$27))*7+(COLUMN(AB32)-COLUMN($X$27)+1)),"",$X$25-(WEEKDAY($X$25,1)-(start_day-1))-IF((WEEKDAY($X$25,1)-(start_day-1))<=0,7,0)+(ROW(AB32)-ROW($X$27))*7+(COLUMN(AB32)-COLUMN($X$27)+1)) | AC32: =IF(MONTH($X$25)<>MONTH($X$25-(WEEKDAY($X$25,1)-(start_day-1))-IF((WEEKDAY($X$25,1)-(start_day-1))<=0,7,0)+(ROW(AC32)-ROW($X$27))*7+(COLUMN(AC32)-COLUMN($X$27)+1)),"",$X$25-(WEEKDAY($X$25,1)-(start_day-1))-IF((WEEKDAY($X$25,1)-(start_day-1))<=0,7,0)+(ROW(AC32)-ROW($X$27))*7+(COLUMN(AC32)-COLUMN($X$27)+1)) | AD32: =IF(MONTH($X$25)<>MONTH($X$25-(WEEKDAY($X$25,1)-(start_day-1))-IF((WEEKDAY($X$25,1)-(start_day-1))<=0,7,0)+(ROW(AD32)-ROW($X$27))*7+(COLUMN(AD32)-COLUMN($X$27)+1)),"",$X$25-(WEEKDAY($X$25,1)-(start_day-1))-IF((WEEKDAY($X$25,1)-(start_day-1))<=0,7,0)+(ROW(AD32)-ROW($X$27))*7+(COLUMN(AD32)-COLUMN($X$27)+1))
D36: Day of Weeks Tracking
E37: M, T | F37: W, TH | G37: F & Sun. | I37: Sat.
D38: Hard | E38: =COUNTIF($E$5:$H$21,"*Hard*") | F38: =COUNTIF($I$5:$N$21,"*Hard*") | G38: =COUNTIF($O$5:$V$21,"*Hard*") | H38: =COUNTIF($C$5:$D$21,"*Hard*") | I38: =COUNTIF($W$5:$AD$21,"*Hard*")
D39: Oehm | E39: =COUNTIF($E$5:$H$21,"*Oehm*") | F39: =COUNTIF($I$5:$N$21,"*Oehm*") | G39: =COUNTIF($O$5:$V$21,"*Oehm*") | H39: =COUNTIF($C$5:$D$21,"*Oehm*") | I39: =COUNTIF($W$5:$AD$21,"*Oehm*")
D40: Schutt | E40: =COUNTIF($E$5:$H$21,"*Schutt*") | F40: =COUNTIF($I$5:$N$21,"*Schutt*") | G40: =COUNTIF($O$5:$V$21,"*Schutt*") | H40: =COUNTIF($C$5:$D$21,"*Schutt*") | I40: =COUNTIF($W$5:$AD$21,"*Schutt*")
D41: Stanek | E41: =COUNTIF($E$5:$H$21,"*Stanek*") | F41: =COUNTIF($I$5:$N$21,"*Stanek*") | G41: =COUNTIF($O$5:$V$21,"*Stanek*") | H41: =COUNTIF($C$5:$D$21,"*Stanek*") | I41: =COUNTIF($W$5:$AD$21,"*Stanek*")
D42: Strand | E42: =COUNTIF($E$5:$H$21,"*Strand*") | F42: =COUNTIF($I$5:$N$21,"*Strand*") | G42: =COUNTIF($O$5:$V$21,"*Strand*") | H42: =COUNTIF($C$5:$D$21,"*Strand*") | I42: =COUNTIF($W$5:$AD$21,"*Strand*")
D43: Wohlgemuth | E43: =COUNTIF($E$5:$H$21,"*Wohlgemuth*") | F43: =COUNTIF($I$5:$N$21,"*Wohlgemuth*") | G43: =COUNTIF($O$5:$V$21,"*Wohlgemuth*") | H43: =COUNTIF($C$5:$D$21,"*Wohlgemuth*") | I43: =COUNTIF($W$5:$AD$21,"*Wohlgemuth*")
D45: Beutel | E45: =COUNTIF($E$5:$H$21,"*Beutel*") | F45: =COUNTIF($I$5:$N$21,"*Beutel*") | G45: =COUNTIF($O$5:$V$21,"*Beutel*") | H45: =COUNTIF($C$5:$D$21,"*Beutel*") | I45: =COUNTIF($W$5:$AD$21,"*Beutel*")
D46: Bottke | E46: =COUNTIF($E$5:$H$21,"*Bottke*") | F46: =COUNTIF($I$5:$N$21,"*Bottke*") | G46: =COUNTIF($O$5:$V$21,"*Bottke*") | H46: =COUNTIF($C$5:$D$21,"*Bottke*") | I46: =COUNTIF($W$5:$AD$21,"*Bottke*")
D47: Bower | E47: =COUNTIF($E$5:$H$21,"*Bower*") | F47: =COUNTIF($I$5:$N$21,"*Bower*") | G47: =COUNTIF($O$5:$V$21,"*Bower*") | H47: =COUNTIF($C$5:$D$21,"*Bower*") | I47: =COUNTIF($W$5:$AD$21,"*Bower*")
D48: Gaspar | E48: =COUNTIF($E$5:$H$21,"*Gaspar*") | F48: =COUNTIF($I$5:$N$21,"*Gaspar*") | G48: =COUNTIF($O$5:$V$21,"*Gaspar*") | H48: =COUNTIF($C$5:$D$21,"*Gaspar*") | I48: =COUNTIF($W$5:$AD$21,"*Gaspar*")
D49: Kendrick | E49: =COUNTIF($E$5:$H$21,"*Kendrick*") | F49: =COUNTIF($I$5:$N$21,"*Kendrick*") | G49: =COUNTIF($O$5:$V$21,"*Kendrick*") | H49: =COUNTIF($C$5:$D$21,"*Kendrick*") | I49: =COUNTIF($W$5:$AD$21,"*Kendrick*")
...

Sheet August
AG1: Call Variances
C2: =DATE('2026'!P8,8,1) | AG2: Away: CBP - 2 weeks: Lux Peds Inpatient: Schutt Med A: Mautino/Patel/Wohlgemuth OB: Gaspar | AK2: GYN/CM: Kendrick NICU: Sublette R3 - Ortho: R2 - Peds: Beutel Derm: Ultrasound:
C4: =C5 | E4: =E5 | G4: =G5 | I4: =I5 | K4: =K5 | O4: =O5 | W4: =W5 | AG4: Tracking Data
C5: =$C$2-(WEEKDAY($C$2,1)-(start_day-1))-IF((WEEKDAY($C$2,1)-(start_day-1))<=0,7,0)+1 | E5: =C5+1 | G5: =E5+1 | I5: =G5+1 | K5: =I5+1 | O5: =K5+1 | W5: =O5+1 | AG5: Interns | AH5: Hard | AI5: Oehm | AJ5: Schutt | AK5: Stanek | AL5: Strand | AM5: Wohlgemuth | AN5: Total
W6: Hard Lux | AH6: =COUNTIF($C$5:$AD$21,"*Hard*") | AI6: =COUNTIF($C$5:$AD$21,"*Oehm*") | AJ6: =COUNTIF($C$5:$AD$21,"*Schutt*") | AK6: =COUNTIF($C$5:$AD$21,"*Stanek*") | AL6: =COUNTIF($C$5:$AD$21,"*Strand*") | AM6: =COUNTIF($C$5:$AD$21,"*Wohlgemuth*") | AN6: =SUM(AH6:AM6)
C7: =W5+1
E8: =C7+1 | G8: =E8+1 | I8: =G8+1 | K8: =I8+1 | O8: =K8+1 | W8: =O8+1 | AG8: 2nd Years | AH8: Beutel | AI8: Bottke | AJ8: Bower | AK8: Gaspar | AL8: Kendrick | AM8: Patel | AN8: Sublette | AO8: Total
C9: Strand Gaspar | E9: Hard Mudondo | G9: Hard Gaspar | I9: Hard Bottke | K9: Hard Johnson | O9: Hard Mautino | W9: Stanek Bottke | AH9: =COUNTIF($C$5:$AD$21,"*Beutel*") | AI9: =COUNTIF($C$5:$AD$21,"*Bottke*") | AJ9: =COUNTIF($C$5:$AD$21,"*Bower*") | AK9: =COUNTIF($C$5:$AD$21,"*Gaspar*") | AL9: =COUNTIF($C$5:$AD$21,"*Kendrick*") | AM9: =COUNTIF($C$5:$AD$21,"*Patel*") | AN9: =COUNTIF($C$5:$AD$21,"*Sublette*") | AO9: =SUM(AH9:AN9)
C10: =W8+1
E11: =C10+1 | G11: =E11+1 | I11: =G11+1 | K11: =I11+1 | O11: =K11+1 | W11: =O11+1 | AG11: 3rd Years | AH11: Johnson | AI11: Lux | AJ11: Mautino | AK11: Mudondo | AL11: Total
C12: Wohlgemuth Gaspar | E12: Hard Mautino | G12: Hard Mudondo | I12: Hard Johnson | K12: Hard Bottke | O12: Hard Kendrick | W12: Stanek Mautino | AH12: =COUNTIF($C$5:$AD$21,"*Johnson*") | AI12: =COUNTIF($C$5:$AD$21,"*Lux*") | AJ12: =COUNTIF($C$5:$AD$21,"*Mautino*") | AK12: =COUNTIF($C$5:$AD$21,"*Mudondo*") | AL12: =SUM(AH12:AK12)
C13: =W11+1
E14: =C13+1 | G14: =E14+1 | I14: =G14+1 | K14: =I14+1 | O14: =K14+1 | W14: =O14+1
C15: Strand Bottke | E15: Oehm Sublette | G15: Oehm Beutel | I15: Oehm Mautino | K15: Oehm Sublette | O15: Oehm Mautino | W15: Wohlgemuth Johnson | AG15: *Strand Sat-Sunday
C16: =W14+1
E17: =C16+1 | G17: =E17+1 | I17: =G17+1 | K17: =I17+1 | O17: =K17+1 | W17: =O17+1
C18: Hard Patel | E18: Oehm Mudondo | G18: Oehm Sublette | I18: Oehm Gaspar | K18: Oehm Mautino | O18: Oehm Johnson | W18: Stanek Bottke
C19: =W17+1
E20: =C19+1 | G20: =E20+1 | I20: =G20+1 | K20: =I20+1 | O20: =K20+1 | W20: =O20+1
C21: Hard Patel | E21: Stanek Mautino
C25: Notes | O25: =DATE(YEAR(C2),MONTH(C2)-1,1) | X25: =DATE(YEAR(C2),MONTH(C2)+1,1)
O26: =INDEX({"S";"M";"T";"W";"T";"F";"S"},1+MOD(start_day+1-2,7)) | P26: =INDEX({"S";"M";"T";"W";"T";"F";"S"},1+MOD(start_day+2-2,7)) | Q26: =INDEX({"S";"M";"T";"W";"T";"F";"S"},1+MOD(start_day+3-2,7)) | R26: =INDEX({"S";"M";"T";"W";"T";"F";"S"},1+MOD(start_day+4-2,7)) | S26: =INDEX({"S";"M";"T";"W";"T";"F";"S"},1+MOD(start_day+5-2,7)) | T26: =INDEX({"S";"M";"T";"W";"T";"F";"S"},1+MOD(start_day+6-2,7)) | U26: =INDEX({"S";"M";"T";"W";"T";"F";"S"},1+MOD(start_day+7-2,7)) | X26: =INDEX({"S";"M";"T";"W";"T";"F";"S"},1+MOD(start_day+1-2,7)) | Y26: =INDEX({"S";"M";"T";"W";"T";"F";"S"},1+MOD(start_day+2-2,7)) | Z26: =INDEX({"S";"M";"T";"W";"T";"F";"S"},1+MOD(start_day+3-2,7)) | AA26: =INDEX({"S";"M";"T";"W";"T";"F";"S"},1+MOD(start_day+4-2,7)) | AB26: =INDEX({"S";"M";"T";"W";"T";"F";"S"},1+MOD(start_day+5-2,7)) | AC26: =INDEX({"S";"M";"T";"W";"T";"F";"S"},1+MOD(start_day+6-2,7)) | AD26: =INDEX({"S";"M";"T";"W";"T";"F";"S"},1+MOD(start_day+7-2,7))
O27: =IF(MONTH($O$25)<>MONTH($O$25-(WEEKDAY($O$25,1)-(start_day-1))-IF((WEEKDAY($O$25,1)-(start_day-1))<=0,7,0)+(ROW(O27)-ROW($O$27))*7+(COLUMN(O27)-COLUMN($O$27)+1)),"",$O$25-(WEEKDAY($O$25,1)-(start_day-1))-IF((WEEKDAY($O$25,1)-(start_day-1))<=0,7,0)+(ROW(O27)-ROW($O$27))*7+(COLUMN(O27)-COLUMN($O$27)+1)) | P27: =IF(MONTH($O$25)<>MONTH($O$25-(WEEKDAY($O$25,1)-(start_day-1))-IF((WEEKDAY($O$25,1)-(start_day-1))<=0,7,0)+(ROW(P27)-ROW($O$27))*7+(COLUMN(P27)-COLUMN($O$27)+1)),"",$O$25-(WEEKDAY($O$25,1)-(start_day-1))-IF((WEEKDAY($O$25,1)-(start_day-1))<=0,7,0)+(ROW(P27)-ROW($O$27))*7+(COLUMN(P27)-COLUMN($O$27)+1)) | Q27: =IF(MONTH($O$25)<>MONTH($O$25-(WEEKDAY($O$25,1)-(start_day-1))-IF((WEEKDAY($O$25,1)-(start_day-1))<=0,7,0)+(ROW(Q27)-ROW($O$27))*7+(COLUMN(Q27)-COLUMN($O$27)+1)),"",$O$25-(WEEKDAY($O$25,1)-(start_day-1))-IF((WEEKDAY($O$25,1)-(start_day-1))<=0,7,0)+(ROW(Q27)-ROW($O$27))*7+(COLUMN(Q27)-COLUMN($O$27)+1)) | R27: =IF(MONTH($O$25)<>MONTH($O$25-(WEEKDAY($O$25,1)-(start_day-1))-IF((WEEKDAY($O$25,1)-(start_day-1))<=0,7,0)+(ROW(R27)-ROW($O$27))*7+(COLUMN(R27)-COLUMN($O$27)+1)),"",$O$25-(WEEKDAY($O$25,1)-(start_day-1))-IF((WEEKDAY($O$25,1)-(start_day-1))<=0,7,0)+(ROW(R27)-ROW($O$27))*7+(COLUMN(R27)-COLUMN($O$27)+1)) | S27: =IF(MONTH($O$25)<>MONTH($O$25-(WEEKDAY($O$25,1)-(start_day-1))-IF((WEEKDAY($O$25,1)-(start_day-1))<=0,7,0)+(ROW(S27)-ROW($O$27))*7+(COLUMN(S27)-COLUMN($O$27)+1)),"",$O$25-(WEEKDAY($O$25,1)-(start_day-1))-IF((WEEKDAY($O$25,1)-(start_day-1))<=0,7,0)+(ROW(S27)-ROW($O$27))*7+(COLUMN(S27)-COLUMN($O$27)+1)) | T27: =IF(MONTH($O$25)<>MONTH($O$25-(WEEKDAY($O$25,1)-(start_day-1))-IF((WEEKDAY($O$25,1)-(start_day-1))<=0,7,0)+(ROW(T27)-ROW($O$27))*7+(COLUMN(T27)-COLUMN($O$27)+1)),"",$O$25-(WEEKDAY($O$25,1)-(start_day-1))-IF((WEEKDAY($O$25,1)-(start_day-1))<=0,7,0)+(ROW(T27)-ROW($O$27))*7+(COLUMN(T27)-COLUMN($O$27)+1)) | U27: =IF(MONTH($O$25)<>MONTH($O$25-(WEEKDAY($O$25,1)-(start_day-1))-IF((WEEKDAY($O$25,1)-(start_day-1))<=0,7,0)+(ROW(U27)-ROW($O$27))*7+(COLUMN(U27)-COLUMN($O$27)+1)),"",$O$25-(WEEKDAY($O$25,1)-(start_day-1))-IF((WEEKDAY($O$25,1)-(start_day-1))<=0,7,0)+(ROW(U27)-ROW($O$27))*7+(COLUMN(U27)-COLUMN($O$27)+1)) | X27: =IF(MONTH($X$25)<>MONTH($X$25-(WEEKDAY($X$25,1)-(start_day-1))-IF((WEEKDAY($X$25,1)-(start_day-1))<=0,7,0)+(ROW(X27)-ROW($X$27))*7+(COLUMN(X27)-COLUMN($X$27)+1)),"",$X$25-(WEEKDAY($X$25,1)-(start_day-1))-IF((WEEKDAY($X$25,1)-(start_day-1))<=0,7,0)+(ROW(X27)-ROW($X$27))*7+(COLUMN(X27)-COLUMN($X$27)+1)) | Y27: =IF(MONTH($X$25)<>MONTH($X$25-(WEEKDAY($X$25,1)-(start_day-1))-IF((WEEKDAY($X$25,1)-(start_day-1))<=0,7,0)+(ROW(Y27)-ROW($X$27))*7+(COLUMN(Y27)-COLUMN($X$27)+1)),"",$X$25-(WEEKDAY($X$25,1)-(start_day-1))-IF((WEEKDAY($X$25,1)-(start_day-1))<=0,7,0)+(ROW(Y27)-ROW($X$27))*7+(COLUMN(Y27)-COLUMN($X$27)+1)) | Z27: =IF(MONTH($X$25)<>MONTH($X$25-(WEEKDAY($X$25,1)-(start_day-1))-IF((WEEKDAY($X$25,1)-(start_day-1))<=0,7,0)+(ROW(Z27)-ROW($X$27))*7+(COLUMN(Z27)-COLUMN($X$27)+1)),"",$X$25-(WEEKDAY($X$25,1)-(start_day-1))-IF((WEEKDAY($X$25,1)-(start_day-1))<=0,7,0)+(ROW(Z27)-ROW($X$27))*7+(COLUMN(Z27)-COLUMN($X$27)+1)) | AA27: =IF(MONTH($X$25)<>MONTH($X$25-(WEEKDAY($X$25,1)-(start_day-1))-IF((WEEKDAY($X$25,1)-(start_day-1))<=0,7,0)+(ROW(AA27)-ROW($X$27))*7+(COLUMN(AA27)-COLUMN($X$27)+1)),"",$X$25-(WEEKDAY($X$25,1)-(start_day-1))-IF((WEEKDAY($X$25,1)-(start_day-1))<=0,7,0)+(ROW(AA27)-ROW($X$27))*7+(COLUMN(AA27)-COLUMN($X$27)+1)) | AB27: =IF(MONTH($X$25)<>MONTH($X$25-(WEEKDAY($X$25,1)-(start_day-1))-IF((WEEKDAY($X$25,1)-(start_day-1))<=0,7,0)+(ROW(AB27)-ROW($X$27))*7+(COLUMN(AB27)-COLUMN($X$27)+1)),"",$X$25-(WEEKDAY($X$25,1)-(start_day-1))-IF((WEEKDAY($X$25,1)-(start_day-1))<=0,7,0)+(ROW(AB27)-ROW($X$27))*7+(COLUMN(AB27)-COLUMN($X$27)+1)) | AC27: =IF(MONTH($X$25)<>MONTH($X$25-(WEEKDAY($X$25,1)-(start_day-1))-IF((WEEKDAY($X$25,1)-(start_day-1))<=0,7,0)+(ROW(AC27)-ROW($X$27))*7+(COLUMN(AC27)-COLUMN($X$27)+1)),"",$X$25-(WEEKDAY($X$25,1)-(start_day-1))-IF((WEEKDAY($X$25,1)-(start_day-1))<=0,7,0)+(ROW(AC27)-ROW($X$27))*7+(COLUMN(AC27)-COLUMN($X$27)+1)) | AD27: =IF(MONTH($X$25)<>MONTH($X$25-(WEEKDAY($X$25,1)-(start_day-1))-IF((WEEKDAY($X$25,1)-(start_day-1))<=0,7,0)+(ROW(AD27)-ROW($X$27))*7+(COLUMN(AD27)-COLUMN($X$27)+1)),"",$X$25-(WEEKDAY($X$25,1)-(start_day-1))-IF((WEEKDAY($X$25,1)-(start_day-1))<=0,7,0)+(ROW(AD27)-ROW($X$27))*7+(COLUMN(AD27)-COLUMN($X$27)+1))
O28: =IF(MONTH($O$25)<>MONTH($O$25-(WEEKDAY($O$25,1)-(start_day-1))-IF((WEEKDAY($O$25,1)-(start_day-1))<=0,7,0)+(ROW(O28)-ROW($O$27))*7+(COLUMN(O28)-COLUMN($O$27)+1)),"",$O$25-(WEEKDAY($O$25,1)-(start_day-1))-IF((WEEKDAY($O$25,1)-(start_day-1))<=0,7,0)+(ROW(O28)-ROW($O$27))*7+(COLUMN(O28)-COLUMN($O$27)+1)) | P28: =IF(MONTH($O$25)<>MONTH($O$25-(WEEKDAY($O$25,1)-(start_day-1))-IF((WEEKDAY($O$25,1)-(start_day-1))<=0,7,0)+(ROW(P28)-ROW($O$27))*7+(COLUMN(P28)-COLUMN($O$27)+1)),"",$O$25-(WEEKDAY($O$25,1)-(start_day-1))-IF((WEEKDAY($O$25,1)-(start_day-1))<=0,7,0)+(ROW(P28)-ROW($O$27))*7+(COLUMN(P28)-COLUMN($O$27)+1)) | Q28: =IF(MONTH($O$25)<>MONTH($O$25-(WEEKDAY($O$25,1)-(start_day-1))-IF((WEEKDAY($O$25,1)-(start_day-1))<=0,7,0)+(ROW(Q28)-ROW($O$27))*7+(COLUMN(Q28)-COLUMN($O$27)+1)),"",$O$25-(WEEKDAY($O$25,1)-(start_day-1))-IF((WEEKDAY($O$25,1)-(start_day-1))<=0,7,0)+(ROW(Q28)-ROW($O$27))*7+(COLUMN(Q28)-COLUMN($O$27)+1)) | R28: =IF(MONTH($O$25)<>MONTH($O$25-(WEEKDAY($O$25,1)-(start_day-1))-IF((WEEKDAY($O$25,1)-(start_day-1))<=0,7,0)+(ROW(R28)-ROW($O$27))*7+(COLUMN(R28)-COLUMN($O$27)+1)),"",$O$25-(WEEKDAY($O$25,1)-(start_day-1))-IF((WEEKDAY($O$25,1)-(start_day-1))<=0,7,0)+(ROW(R28)-ROW($O$27))*7+(COLUMN(R28)-COLUMN($O$27)+1)) | S28: =IF(MONTH($O$25)<>MONTH($O$25-(WEEKDAY($O$25,1)-(start_day-1))-IF((WEEKDAY($O$25,1)-(start_day-1))<=0,7,0)+(ROW(S28)-ROW($O$27))*7+(COLUMN(S28)-COLUMN($O$27)+1)),"",$O$25-(WEEKDAY($O$25,1)-(start_day-1))-IF((WEEKDAY($O$25,1)-(start_day-1))<=0,7,0)+(ROW(S28)-ROW($O$27))*7+(COLUMN(S28)-COLUMN($O$27)+1)) | T28: =IF(MONTH($O$25)<>MONTH($O$25-(WEEKDAY($O$25,1)-(start_day-1))-IF((WEEKDAY($O$25,1)-(start_day-1))<=0,7,0)+(ROW(T28)-ROW($O$27))*7+(COLUMN(T28)-COLUMN($O$27)+1)),"",$O$25-(WEEKDAY($O$25,1)-(start_day-1))-IF((WEEKDAY($O$25,1)-(start_day-1))<=0,7,0)+(ROW(T28)-ROW($O$27))*7+(COLUMN(T28)-COLUMN($O$27)+1)) | U28: =IF(MONTH($O$25)<>MONTH($O$25-(WEEKDAY($O$25,1)-(start_day-1))-IF((WEEKDAY($O$25,1)-(start_day-1))<=0,7,0)+(ROW(U28)-ROW($O$27))*7+(COLUMN(U28)-COLUMN($O$27)+1)),"",$O$25-(WEEKDAY($O$25,1)-(start_day-1))-IF((WEEKDAY($O$25,1)-(start_day-1))<=0,7,0)+(ROW(U28)-ROW($O$27))*7+(COLUMN(U28)-COLUMN($O$27)+1)) | X28: =IF(MONTH($X$25)<>MONTH($X$25-(WEEKDAY($X$25,1)-(start_day-1))-IF((WEEKDAY($X$25,1)-(start_day-1))<=0,7,0)+(ROW(X28)-ROW($X$27))*7+(COLUMN(X28)-COLUMN($X$27)+1)),"",$X$25-(WEEKDAY($X$25,1)-(start_day-1))-IF((WEEKDAY($X$25,1)-(start_day-1))<=0,7,0)+(ROW(X28)-ROW($X$27))*7+(COLUMN(X28)-COLUMN($X$27)+1)) | Y28: =IF(MONTH($X$25)<>MONTH($X$25-(WEEKDAY($X$25,1)-(start_day-1))-IF((WEEKDAY($X$25,1)-(start_day-1))<=0,7,0)+(ROW(Y28)-ROW($X$27))*7+(COLUMN(Y28)-COLUMN($X$27)+1)),"",$X$25-(WEEKDAY($X$25,1)-(start_day-1))-IF((WEEKDAY($X$25,1)-(start_day-1))<=0,7,0)+(ROW(Y28)-ROW($X$27))*7+(COLUMN(Y28)-COLUMN($X$27)+1)) | Z28: =IF(MONTH($X$25)<>MONTH($X$25-(WEEKDAY($X$25,1)-(start_day-1))-IF((WEEKDAY($X$25,1)-(start_day-1))<=0,7,0)+(ROW(Z28)-ROW($X$27))*7+(COLUMN(Z28)-COLUMN($X$27)+1)),"",$X$25-(WEEKDAY($X$25,1)-(start_day-1))-IF((WEEKDAY($X$25,1)-(start_day-1))<=0,7,0)+(ROW(Z28)-ROW($X$27))*7+(COLUMN(Z28)-COLUMN($X$27)+1)) | AA28: =IF(MONTH($X$25)<>MONTH($X$25-(WEEKDAY($X$25,1)-(start_day-1))-IF((WEEKDAY($X$25,1)-(start_day-1))<=0,7,0)+(ROW(AA28)-ROW($X$27))*7+(COLUMN(AA28)-COLUMN($X$27)+1)),"",$X$25-(WEEKDAY($X$25,1)-(start_day-1))-IF((WEEKDAY($X$25,1)-(start_day-1))<=0,7,0)+(ROW(AA28)-ROW($X$27))*7+(COLUMN(AA28)-COLUMN($X$27)+1)) | AB28: =IF(MONTH($X$25)<>MONTH($X$25-(WEEKDAY($X$25,1)-(start_day-1))-IF((WEEKDAY($X$25,1)-(start_day-1))<=0,7,0)+(ROW(AB28)-ROW($X$27))*7+(COLUMN(AB28)-COLUMN($X$27)+1)),"",$X$25-(WEEKDAY($X$25,1)-(start_day-1))-IF((WEEKDAY($X$25,1)-(start_day-1))<=0,7,0)+(ROW(AB28)-ROW($X$27))*7+(COLUMN(AB28)-COLUMN($X$27)+1)) | AC28: =IF(MONTH($X$25)<>MONTH($X$25-(WEEKDAY($X$25,1)-(start_day-1))-IF((WEEKDAY($X$25,1)-(start_day-1))<=0,7,0)+(ROW(AC28)-ROW($X$27))*7+(COLUMN(AC28)-COLUMN($X$27)+1)),"",$X$25-(WEEKDAY($X$25,1)-(start_day-1))-IF((WEEKDAY($X$25,1)-(start_day-1))<=0,7,0)+(ROW(AC28)-ROW($X$27))*7+(COLUMN(AC28)-COLUMN($X$27)+1)) | AD28: =IF(MONTH($X$25)<>MONTH($X$25-(WEEKDAY($X$25,1)-(start_day-1))-IF((WEEKDAY($X$25,1)-(start_day-1))<=0,7,0)+(ROW(AD28)-ROW($X$27))*7+(COLUMN(AD28)-COLUMN($X$27)+1)),"",$X$25-(WEEKDAY($X$25,1)-(start_day-1))-IF((WEEKDAY($X$25,1)-(start_day-1))<=0,7,0)+(ROW(AD28)-ROW($X$27))*7+(COLUMN(AD28)-COLUMN($X$27)+1))
O29: =IF(MONTH($O$25)<>MONTH($O$25-(WEEKDAY($O$25,1)-(start_day-1))-IF((WEEKDAY($O$25,1)-(start_day-1))<=0,7,0)+(ROW(O29)-ROW($O$27))*7+(COLUMN(O29)-COLUMN($O$27)+1)),"",$O$25-(WEEKDAY($O$25,1)-(start_day-1))-IF((WEEKDAY($O$25,1)-(start_day-1))<=0,7,0)+(ROW(O29)-ROW($O$27))*7+(COLUMN(O29)-COLUMN($O$27)+1)) | P29: =IF(MONTH($O$25)<>MONTH($O$25-(WEEKDAY($O$25,1)-(start_day-1))-IF((WEEKDAY($O$25,1)-(start_day-1))<=0,7,0)+(ROW(P29)-ROW($O$27))*7+(COLUMN(P29)-COLUMN($O$27)+1)),"",$O$25-(WEEKDAY($O$25,1)-(start_day-1))-IF((WEEKDAY($O$25,1)-(start_day-1))<=0,7,0)+(ROW(P29)-ROW($O$27))*7+(COLUMN(P29)-COLUMN($O$27)+1)) | Q29: =IF(MONTH($O$25)<>MONTH($O$25-(WEEKDAY($O$25,1)-(start_day-1))-IF((WEEKDAY($O$25,1)-(start_day-1))<=0,7,0)+(ROW(Q29)-ROW($O$27))*7+(COLUMN(Q29)-COLUMN($O$27)+1)),"",$O$25-(WEEKDAY($O$25,1)-(start_day-1))-IF((WEEKDAY($O$25,1)-(start_day-1))<=0,7,0)+(ROW(Q29)-ROW($O$27))*7+(COLUMN(Q29)-COLUMN($O$27)+1)) | R29: =IF(MONTH($O$25)<>MONTH($O$25-(WEEKDAY($O$25,1)-(start_day-1))-IF((WEEKDAY($O$25,1)-(start_day-1))<=0,7,0)+(ROW(R29)-ROW($O$27))*7+(COLUMN(R29)-COLUMN($O$27)+1)),"",$O$25-(WEEKDAY($O$25,1)-(start_day-1))-IF((WEEKDAY($O$25,1)-(start_day-1))<=0,7,0)+(ROW(R29)-ROW($O$27))*7+(COLUMN(R29)-COLUMN($O$27)+1)) | S29: =IF(MONTH($O$25)<>MONTH($O$25-(WEEKDAY($O$25,1)-(start_day-1))-IF((WEEKDAY($O$25,1)-(start_day-1))<=0,7,0)+(ROW(S29)-ROW($O$27))*7+(COLUMN(S29)-COLUMN($O$27)+1)),"",$O$25-(WEEKDAY($O$25,1)-(start_day-1))-IF((WEEKDAY($O$25,1)-(start_day-1))<=0,7,0)+(ROW(S29)-ROW($O$27))*7+(COLUMN(S29)-COLUMN($O$27)+1)) | T29: =IF(MONTH($O$25)<>MONTH($O$25-(WEEKDAY($O$25,1)-(start_day-1))-IF((WEEKDAY($O$25,1)-(start_day-1))<=0,7,0)+(ROW(T29)-ROW($O$27))*7+(COLUMN(T29)-COLUMN($O$27)+1)),"",$O$25-(WEEKDAY($O$25,1)-(start_day-1))-IF((WEEKDAY($O$25,1)-(start_day-1))<=0,7,0)+(ROW(T29)-ROW($O$27))*7+(COLUMN(T29)-COLUMN($O$27)+1)) | U29: =IF(MONTH($O$25)<>MONTH($O$25-(WEEKDAY($O$25,1)-(start_day-1))-IF((WEEKDAY($O$25,1)-(start_day-1))<=0,7,0)+(ROW(U29)-ROW($O$27))*7+(COLUMN(U29)-COLUMN($O$27)+1)),"",$O$25-(WEEKDAY($O$25,1)-(start_day-1))-IF((WEEKDAY($O$25,1)-(start_day-1))<=0,7,0)+(ROW(U29)-ROW($O$27))*7+(COLUMN(U29)-COLUMN($O$27)+1)) | X29: =IF(MONTH($X$25)<>MONTH($X$25-(WEEKDAY($X$25,1)-(start_day-1))-IF((WEEKDAY($X$25,1)-(start_day-1))<=0,7,0)+(ROW(X29)-ROW($X$27))*7+(COLUMN(X29)-COLUMN($X$27)+1)),"",$X$25-(WEEKDAY($X$25,1)-(start_day-1))-IF((WEEKDAY($X$25,1)-(start_day-1))<=0,7,0)+(ROW(X29)-ROW($X$27))*7+(COLUMN(X29)-COLUMN($X$27)+1)) | Y29: =IF(MONTH($X$25)<>MONTH($X$25-(WEEKDAY($X$25,1)-(start_day-1))-IF((WEEKDAY($X$25,1)-(start_day-1))<=0,7,0)+(ROW(Y29)-ROW($X$27))*7+(COLUMN(Y29)-COLUMN($X$27)+1)),"",$X$25-(WEEKDAY($X$25,1)-(start_day-1))-IF((WEEKDAY($X$25,1)-(start_day-1))<=0,7,0)+(ROW(Y29)-ROW($X$27))*7+(COLUMN(Y29)-COLUMN($X$27)+1)) | Z29: =IF(MONTH($X$25)<>MONTH($X$25-(WEEKDAY($X$25,1)-(start_day-1))-IF((WEEKDAY($X$25,1)-(start_day-1))<=0,7,0)+(ROW(Z29)-ROW($X$27))*7+(COLUMN(Z29)-COLUMN($X$27)+1)),"",$X$25-(WEEKDAY($X$25,1)-(start_day-1))-IF((WEEKDAY($X$25,1)-(start_day-1))<=0,7,0)+(ROW(Z29)-ROW($X$27))*7+(COLUMN(Z29)-COLUMN($X$27)+1)) | AA29: =IF(MONTH($X$25)<>MONTH($X$25-(WEEKDAY($X$25,1)-(start_day-1))-IF((WEEKDAY($X$25,1)-(start_day-1))<=0,7,0)+(ROW(AA29)-ROW($X$27))*7+(COLUMN(AA29)-COLUMN($X$27)+1)),"",$X$25-(WEEKDAY($X$25,1)-(start_day-1))-IF((WEEKDAY($X$25,1)-(start_day-1))<=0,7,0)+(ROW(AA29)-ROW($X$27))*7+(COLUMN(AA29)-COLUMN($X$27)+1)) | AB29: =IF(MONTH($X$25)<>MONTH($X$25-(WEEKDAY($X$25,1)-(start_day-1))-IF((WEEKDAY($X$25,1)-(start_day-1))<=0,7,0)+(ROW(AB29)-ROW($X$27))*7+(COLUMN(AB29)-COLUMN($X$27)+1)),"",$X$25-(WEEKDAY($X$25,1)-(start_day-1))-IF((WEEKDAY($X$25,1)-(start_day-1))<=0,7,0)+(ROW(AB29)-ROW($X$27))*7+(COLUMN(AB29)-COLUMN($X$27)+1)) | AC29: =IF(MONTH($X$25)<>MONTH($X$25-(WEEKDAY($X$25,1)-(start_day-1))-IF((WEEKDAY($X$25,1)-(start_day-1))<=0,7,0)+(ROW(AC29)-ROW($X$27))*7+(COLUMN(AC29)-COLUMN($X$27)+1)),"",$X$25-(WEEKDAY($X$25,1)-(start_day-1))-IF((WEEKDAY($X$25,1)-(start_day-1))<=0,7,0)+(ROW(AC29)-ROW($X$27))*7+(COLUMN(AC29)-COLUMN($X$27)+1)) | AD29: =IF(MONTH($X$25)<>MONTH($X$25-(WEEKDAY($X$25,1)-(start_day-1))-IF((WEEKDAY($X$25,1)-(start_day-1))<=0,7,0)+(ROW(AD29)-ROW($X$27))*7+(COLUMN(AD29)-COLUMN($X$27)+1)),"",$X$25-(WEEKDAY($X$25,1)-(start_day-1))-IF((WEEKDAY($X$25,1)-(start_day-1))<=0,7,0)+(ROW(AD29)-ROW($X$27))*7+(COLUMN(AD29)-COLUMN($X$27)+1))
O30: =IF(MONTH($O$25)<>MONTH($O$25-(WEEKDAY($O$25,1)-(start_day-1))-IF((WEEKDAY($O$25,1)-(start_day-1))<=0,7,0)+(ROW(O30)-ROW($O$27))*7+(COLUMN(O30)-COLUMN($O$27)+1)),"",$O$25-(WEEKDAY($O$25,1)-(start_day-1))-IF((WEEKDAY($O$25,1)-(start_day-1))<=0,7,0)+(ROW(O30)-ROW($O$27))*7+(COLUMN(O30)-COLUMN($O$27)+1)) | P30: =IF(MONTH($O$25)<>MONTH($O$25-(WEEKDAY($O$25,1)-(start_day-1))-IF((WEEKDAY($O$25,1)-(start_day-1))<=0,7,0)+(ROW(P30)-ROW($O$27))*7+(COLUMN(P30)-COLUMN($O$27)+1)),"",$O$25-(WEEKDAY($O$25,1)-(start_day-1))-IF((WEEKDAY($O$25,1)-(start_day-1))<=0,7,0)+(ROW(P30)-ROW($O$27))*7+(COLUMN(P30)-COLUMN($O$27)+1)) | Q30: =IF(MONTH($O$25)<>MONTH($O$25-(WEEKDAY($O$25,1)-(start_day-1))-IF((WEEKDAY($O$25,1)-(start_day-1))<=0,7,0)+(ROW(Q30)-ROW($O$27))*7+(COLUMN(Q30)-COLUMN($O$27)+1)),"",$O$25-(WEEKDAY($O$25,1)-(start_day-1))-IF((WEEKDAY($O$25,1)-(start_day-1))<=0,7,0)+(ROW(Q30)-ROW($O$27))*7+(COLUMN(Q30)-COLUMN($O$27)+1)) | R30: =IF(MONTH($O$25)<>MONTH($O$25-(WEEKDAY($O$25,1)-(start_day-1))-IF((WEEKDAY($O$25,1)-(start_day-1))<=0,7,0)+(ROW(R30)-ROW($O$27))*7+(COLUMN(R30)-COLUMN($O$27)+1)),"",$O$25-(WEEKDAY($O$25,1)-(start_day-1))-IF((WEEKDAY($O$25,1)-(start_day-1))<=0,7,0)+(ROW(R30)-ROW($O$27))*7+(COLUMN(R30)-COLUMN($O$27)+1)) | S30: =IF(MONTH($O$25)<>MONTH($O$25-(WEEKDAY($O$25,1)-(start_day-1))-IF((WEEKDAY($O$25,1)-(start_day-1))<=0,7,0)+(ROW(S30)-ROW($O$27))*7+(COLUMN(S30)-COLUMN($O$27)+1)),"",$O$25-(WEEKDAY($O$25,1)-(start_day-1))-IF((WEEKDAY($O$25,1)-(start_day-1))<=0,7,0)+(ROW(S30)-ROW($O$27))*7+(COLUMN(S30)-COLUMN($O$27)+1)) | T30: =IF(MONTH($O$25)<>MONTH($O$25-(WEEKDAY($O$25,1)-(start_day-1))-IF((WEEKDAY($O$25,1)-(start_day-1))<=0,7,0)+(ROW(T30)-ROW($O$27))*7+(COLUMN(T30)-COLUMN($O$27)+1)),"",$O$25-(WEEKDAY($O$25,1)-(start_day-1))-IF((WEEKDAY($O$25,1)-(start_day-1))<=0,7,0)+(ROW(T30)-ROW($O$27))*7+(COLUMN(T30)-COLUMN($O$27)+1)) | U30: =IF(MONTH($O$25)<>MONTH($O$25-(WEEKDAY($O$25,1)-(start_day-1))-IF((WEEKDAY($O$25,1)-(start_day-1))<=0,7,0)+(ROW(U30)-ROW($O$27))*7+(COLUMN(U30)-COLUMN($O$27)+1)),"",$O$25-(WEEKDAY($O$25,1)-(start_day-1))-IF((WEEKDAY($O$25,1)-(start_day-1))<=0,7,0)+(ROW(U30)-ROW($O$27))*7+(COLUMN(U30)-COLUMN($O$27)+1)) | X30: =IF(MONTH($X$25)<>MONTH($X$25-(WEEKDAY($X$25,1)-(start_day-1))-IF((WEEKDAY($X$25,1)-(start_day-1))<=0,7,0)+(ROW(X30)-ROW($X$27))*7+(COLUMN(X30)-COLUMN($X$27)+1)),"",$X$25-(WEEKDAY($X$25,1)-(start_day-1))-IF((WEEKDAY($X$25,1)-(start_day-1))<=0,7,0)+(ROW(X30)-ROW($X$27))*7+(COLUMN(X30)-COLUMN($X$27)+1)) | Y30: =IF(MONTH($X$25)<>MONTH($X$25-(WEEKDAY($X$25,1)-(start_day-1))-IF((WEEKDAY($X$25,1)-(start_day-1))<=0,7,0)+(ROW(Y30)-ROW($X$27))*7+(COLUMN(Y30)-COLUMN($X$27)+1)),"",$X$25-(WEEKDAY($X$25,1)-(start_day-1))-IF((WEEKDAY($X$25,1)-(start_day-1))<=0,7,0)+(ROW(Y30)-ROW($X$27))*7+(COLUMN(Y30)-COLUMN($X$27)+1)) | Z30: =IF(MONTH($X$25)<>MONTH($X$25-(WEEKDAY($X$25,1)-(start_day-1))-IF((WEEKDAY($X$25,1)-(start_day-1))<=0,7,0)+(ROW(Z30)-ROW($X$27))*7+(COLUMN(Z30)-COLUMN($X$27)+1)),"",$X$25-(WEEKDAY($X$25,1)-(start_day-1))-IF((WEEKDAY($X$25,1)-(start_day-1))<=0,7,0)+(ROW(Z30)-ROW($X$27))*7+(COLUMN(Z30)-COLUMN($X$27)+1)) | AA30: =IF(MONTH($X$25)<>MONTH($X$25-(WEEKDAY($X$25,1)-(start_day-1))-IF((WEEKDAY($X$25,1)-(start_day-1))<=0,7,0)+(ROW(AA30)-ROW($X$27))*7+(COLUMN(AA30)-COLUMN($X$27)+1)),"",$X$25-(WEEKDAY($X$25,1)-(start_day-1))-IF((WEEKDAY($X$25,1)-(start_day-1))<=0,7,0)+(ROW(AA30)-ROW($X$27))*7+(COLUMN(AA30)-COLUMN($X$27)+1)) | AB30: =IF(MONTH($X$25)<>MONTH($X$25-(WEEKDAY($X$25,1)-(start_day-1))-IF((WEEKDAY($X$25,1)-(start_day-1))<=0,7,0)+(ROW(AB30)-ROW($X$27))*7+(COLUMN(AB30)-COLUMN($X$27)+1)),"",$X$25-(WEEKDAY($X$25,1)-(start_day-1))-IF((WEEKDAY($X$25,1)-(start_day-1))<=0,7,0)+(ROW(AB30)-ROW($X$27))*7+(COLUMN(AB30)-COLUMN($X$27)+1)) | AC30: =IF(MONTH($X$25)<>MONTH($X$25-(WEEKDAY($X$25,1)-(start_day-1))-IF((WEEKDAY($X$25,1)-(start_day-1))<=0,7,0)+(ROW(AC30)-ROW($X$27))*7+(COLUMN(AC30)-COLUMN($X$27)+1)),"",$X$25-(WEEKDAY($X$25,1)-(start_day-1))-IF((WEEKDAY($X$25,1)-(start_day-1))<=0,7,0)+(ROW(AC30)-ROW($X$27))*7+(COLUMN(AC30)-COLUMN($X$27)+1)) | AD30: =IF(MONTH($X$25)<>MONTH($X$25-(WEEKDAY($X$25,1)-(start_day-1))-IF((WEEKDAY($X$25,1)-(start_day-1))<=0,7,0)+(ROW(AD30)-ROW($X$27))*7+(COLUMN(AD30)-COLUMN($X$27)+1)),"",$X$25-(WEEKDAY($X$25,1)-(start_day-1))-IF((WEEKDAY($X$25,1)-(start_day-1))<=0,7,0)+(ROW(AD30)-ROW($X$27))*7+(COLUMN(AD30)-COLUMN($X$27)+1))
O31: =IF(MONTH($O$25)<>MONTH($O$25-(WEEKDAY($O$25,1)-(start_day-1))-IF((WEEKDAY($O$25,1)-(start_day-1))<=0,7,0)+(ROW(O31)-ROW($O$27))*7+(COLUMN(O31)-COLUMN($O$27)+1)),"",$O$25-(WEEKDAY($O$25,1)-(start_day-1))-IF((WEEKDAY($O$25,1)-(start_day-1))<=0,7,0)+(ROW(O31)-ROW($O$27))*7+(COLUMN(O31)-COLUMN($O$27)+1)) | P31: =IF(MONTH($O$25)<>MONTH($O$25-(WEEKDAY($O$25,1)-(start_day-1))-IF((WEEKDAY($O$25,1)-(start_day-1))<=0,7,0)+(ROW(P31)-ROW($O$27))*7+(COLUMN(P31)-COLUMN($O$27)+1)),"",$O$25-(WEEKDAY($O$25,1)-(start_day-1))-IF((WEEKDAY($O$25,1)-(start_day-1))<=0,7,0)+(ROW(P31)-ROW($O$27))*7+(COLUMN(P31)-COLUMN($O$27)+1)) | Q31: =IF(MONTH($O$25)<>MONTH($O$25-(WEEKDAY($O$25,1)-(start_day-1))-IF((WEEKDAY($O$25,1)-(start_day-1))<=0,7,0)+(ROW(Q31)-ROW($O$27))*7+(COLUMN(Q31)-COLUMN($O$27)+1)),"",$O$25-(WEEKDAY($O$25,1)-(start_day-1))-IF((WEEKDAY($O$25,1)-(start_day-1))<=0,7,0)+(ROW(Q31)-ROW($O$27))*7+(COLUMN(Q31)-COLUMN($O$27)+1)) | R31: =IF(MONTH($O$25)<>MONTH($O$25-(WEEKDAY($O$25,1)-(start_day-1))-IF((WEEKDAY($O$25,1)-(start_day-1))<=0,7,0)+(ROW(R31)-ROW($O$27))*7+(COLUMN(R31)-COLUMN($O$27)+1)),"",$O$25-(WEEKDAY($O$25,1)-(start_day-1))-IF((WEEKDAY($O$25,1)-(start_day-1))<=0,7,0)+(ROW(R31)-ROW($O$27))*7+(COLUMN(R31)-COLUMN($O$27)+1)) | S31: =IF(MONTH($O$25)<>MONTH($O$25-(WEEKDAY($O$25,1)-(start_day-1))-IF((WEEKDAY($O$25,1)-(start_day-1))<=0,7,0)+(ROW(S31)-ROW($O$27))*7+(COLUMN(S31)-COLUMN($O$27)+1)),"",$O$25-(WEEKDAY($O$25,1)-(start_day-1))-IF((WEEKDAY($O$25,1)-(start_day-1))<=0,7,0)+(ROW(S31)-ROW($O$27))*7+(COLUMN(S31)-COLUMN($O$27)+1)) | T31: =IF(MONTH($O$25)<>MONTH($O$25-(WEEKDAY($O$25,1)-(start_day-1))-IF((WEEKDAY($O$25,1)-(start_day-1))<=0,7,0)+(ROW(T31)-ROW($O$27))*7+(COLUMN(T31)-COLUMN($O$27)+1)),"",$O$25-(WEEKDAY($O$25,1)-(start_day-1))-IF((WEEKDAY($O$25,1)-(start_day-1))<=0,7,0)+(ROW(T31)-ROW($O$27))*7+(COLUMN(T31)-COLUMN($O$27)+1)) | U31: =IF(MONTH($O$25)<>MONTH($O$25-(WEEKDAY($O$25,1)-(start_day-1))-IF((WEEKDAY($O$25,1)-(start_day-1))<=0,7,0)+(ROW(U31)-ROW($O$27))*7+(COLUMN(U31)-COLUMN($O$27)+1)),"",$O$25-(WEEKDAY($O$25,1)-(start_day-1))-IF((WEEKDAY($O$25,1)-(start_day-1))<=0,7,0)+(ROW(U31)-ROW($O$27))*7+(COLUMN(U31)-COLUMN($O$27)+1)) | X31: =IF(MONTH($X$25)<>MONTH($X$25-(WEEKDAY($X$25,1)-(start_day-1))-IF((WEEKDAY($X$25,1)-(start_day-1))<=0,7,0)+(ROW(X31)-ROW($X$27))*7+(COLUMN(X31)-COLUMN($X$27)+1)),"",$X$25-(WEEKDAY($X$25,1)-(start_day-1))-IF((WEEKDAY($X$25,1)-(start_day-1))<=0,7,0)+(ROW(X31)-ROW($X$27))*7+(COLUMN(X31)-COLUMN($X$27)+1)) | Y31: =IF(MONTH($X$25)<>MONTH($X$25-(WEEKDAY($X$25,1)-(start_day-1))-IF((WEEKDAY($X$25,1)-(start_day-1))<=0,7,0)+(ROW(Y31)-ROW($X$27))*7+(COLUMN(Y31)-COLUMN($X$27)+1)),"",$X$25-(WEEKDAY($X$25,1)-(start_day-1))-IF((WEEKDAY($X$25,1)-(start_day-1))<=0,7,0)+(ROW(Y31)-ROW($X$27))*7+(COLUMN(Y31)-COLUMN($X$27)+1)) | Z31: =IF(MONTH($X$25)<>MONTH($X$25-(WEEKDAY($X$25,1)-(start_day-1))-IF((WEEKDAY($X$25,1)-(start_day-1))<=0,7,0)+(ROW(Z31)-ROW($X$27))*7+(COLUMN(Z31)-COLUMN($X$27)+1)),"",$X$25-(WEEKDAY($X$25,1)-(start_day-1))-IF((WEEKDAY($X$25,1)-(start_day-1))<=0,7,0)+(ROW(Z31)-ROW($X$27))*7+(COLUMN(Z31)-COLUMN($X$27)+1)) | AA31: =IF(MONTH($X$25)<>MONTH($X$25-(WEEKDAY($X$25,1)-(start_day-1))-IF((WEEKDAY($X$25,1)-(start_day-1))<=0,7,0)+(ROW(AA31)-ROW($X$27))*7+(COLUMN(AA31)-COLUMN($X$27)+1)),"",$X$25-(WEEKDAY($X$25,1)-(start_day-1))-IF((WEEKDAY($X$25,1)-(start_day-1))<=0,7,0)+(ROW(AA31)-ROW($X$27))*7+(COLUMN(AA31)-COLUMN($X$27)+1)) | AB31: =IF(MONTH($X$25)<>MONTH($X$25-(WEEKDAY($X$25,1)-(start_day-1))-IF((WEEKDAY($X$25,1)-(start_day-1))<=0,7,0)+(ROW(AB31)-ROW($X$27))*7+(COLUMN(AB31)-COLUMN($X$27)+1)),"",$X$25-(WEEKDAY($X$25,1)-(start_day-1))-IF((WEEKDAY($X$25,1)-(start_day-1))<=0,7,0)+(ROW(AB31)-ROW($X$27))*7+(COLUMN(AB31)-COLUMN($X$27)+1)) | AC31: =IF(MONTH($X$25)<>MONTH($X$25-(WEEKDAY($X$25,1)-(start_day-1))-IF((WEEKDAY($X$25,1)-(start_day-1))<=0,7,0)+(ROW(AC31)-ROW($X$27))*7+(COLUMN(AC31)-COLUMN($X$27)+1)),"",$X$25-(WEEKDAY($X$25,1)-(start_day-1))-IF((WEEKDAY($X$25,1)-(start_day-1))<=0,7,0)+(ROW(AC31)-ROW($X$27))*7+(COLUMN(AC31)-COLUMN($X$27)+1)) | AD31: =IF(MONTH($X$25)<>MONTH($X$25-(WEEKDAY($X$25,1)-(start_day-1))-IF((WEEKDAY($X$25,1)-(start_day-1))<=0,7,0)+(ROW(AD31)-ROW($X$27))*7+(COLUMN(AD31)-COLUMN($X$27)+1)),"",$X$25-(WEEKDAY($X$25,1)-(start_day-1))-IF((WEEKDAY($X$25,1)-(start_day-1))<=0,7,0)+(ROW(AD31)-ROW($X$27))*7+(COLUMN(AD31)-COLUMN($X$27)+1))
